Workbook
Name _splatka: 'prijem - EUR'!$F$126
Name bridge_YN: [1]CALC!$K$18
Name doba_m: 'prijem - EUR'!$F$50
Name doba_m_z: 'prijem -inna mena'!$F$55
Name hladaj: 'prijem - EUR'!$D$126
Name hladaj_ks: 'prijem - EUR'!$D$127
Name ks_splatka: 'prijem - EUR'!$F$127
Name LCI: 'prijem - EUR'!#REF!
Name LCI_z: 'prijem -inna mena'!#REF!
Name ltv: 'prijem - EUR'!#REF!
Name ltv_high: 'prijem - EUR'!$F$70
Name ltv_high_z: 'prijem -inna mena'!$F$61
Name ltv_low: 'prijem - EUR'!#REF!
Name poplatok_t0: 'prijem - EUR'!$F$85
Name pv_splatok: 'prijem - EUR'!$E$126
Name pv_splatok_ks: 'prijem - EUR'!$E$127
Name rpmn: 'prijem - EUR'!$F$93
Name rpmn_ks: 'prijem - EUR'!$F$94
Name rpmn_ks_z: 'prijem -inna mena'!$F$96
Name rpmn_z: 'prijem -inna mena'!$F$95
Name splatka: 'prijem - EUR'!$F$84
Name splatka_ks: 'prijem - EUR'!$F$89
Name splatka_ks_z: 'prijem -inna mena'!$F$92
Name splatka_z: 'prijem -inna mena'!$F$89
Name urokova_sadzba: 'prijem - EUR'!$F$73
Name urokova_sadzba_z: 'prijem -inna mena'!$F$78
Name vyska_uveru: 'prijem - EUR'!$F$48
Name vyska_uveru_LI: 'prijem - EUR'!$F$49
Name vyska_uveru_LI_z: 'prijem -inna mena'!$F$54
Name vyska_uveru_z: 'prijem -inna mena'!$F$53
Name zabezpecenie: 'prijem - EUR'!$F$51
Name zabezpecenie_z: 'prijem -inna mena'!$F$56

Sheet Úrokový lístok

Sheet prijem - EUR
C1: Kalkulačka mHypotéka
D3: Dátum zadania do systému | F3: 45860
F4: =IF(ISBLANK(F3),"DÁTUM PODANIA!","OK") -> OK
D5: Číslo žiadosti
D7: Mesačný čistý príjem domácnosti v EUR | F7: =MAX(F8+F11+F14+F17-F9-F12-F15-F18,0) -> 0 | I7: Minimální věk
D8: Čistý príjem žiadateľa č.1 | F8: 0 | I8: =IF(F20=4,MIN(F22,F24,F26,F28),IF(F20=3,MIN(F22,F24,F26),IF(F20=2,MIN(F22,F24),F22))) -> 0
D9: z toho príjem z výživného a sirotského dôchodku | F9: 0
D10: Náklady bývanie žiadateľa č.1 | F10: 0
D11: Čistý príjem žiadateľa č.2 | F11: 0
D12: z toho príjem z výživného a sirotského dôchodku | F12: 0
D13: Náklady bývanie žiadateľa č.2 | F13: 0
D14: Čistý príjem žiadateľa č.3 | F14: 0
D15: z toho príjem z výživného a sirotského dôchodku | F15: 0
D16: Náklady bývanie žiadateľa č.3 | F16: 0
D17: Čistý príjem žiadateľa č.4 | F17: 0
D18: z toho príjem z výživného a sirotského dôchodku | F18: 0
D19: Náklady bývanie žiadateľa č.4 | F19: 0
D20: Počet žiadatelov | F20: 1
D21: Dátum narodenia žiadateľa č. 1 | I21: =IF(F22<41,8,IF(F22+doba_m/12<65,8,MAX(8-0.25*(F22-40),3))) -> 8
D22: Vek žiadateľa č.1 na limity | F22: =IF(F21="",0,IF(AND(DAY(F3)=DAY(F21),MONTH(F3)=MONTH(F21)),YEAR(F3)-YEAR(F21),FLOOR(YEARFRAC(F21,F3,1),1))) -> 0
D23: Dátum narodenia žiadateľa č. 2 | I23: =IF(F24<41,8,IF(F24+doba_m/12<65,8,MAX(8-0.25*(F24-40),3))) -> 8
D24: Vek žiadateľa č.2 na limity | F24: =IF(F23="",0,IF(AND(DAY(F3)=DAY(F23),MONTH(F3)=MONTH(F23)),YEAR(F3)-YEAR(F23),FLOOR(YEARFRAC(F23,F3,1),1))) -> 0
D25: Dátum narodenia žiadateľa č. 3 | I25: =IF(F26<41,8,IF(F26+doba_m/12<65,8,MAX(8-0.25*(F26-40),3))) -> 8
D26: Vek žiadateľa č.3 na limity | F26: =IF(F25="",0,IF(AND(DAY(F3)=DAY(F25),MONTH(F3)=MONTH(F25)),YEAR(F3)-YEAR(F25),FLOOR(YEARFRAC(F25,F3,1),1))) -> 0
D27: Dátum narodenia žiadateľa č. 4 | I27: =IF(F28<41,8,IF(F28+doba_m/12<65,8,MAX(8-0.25*(F28-40),3))) -> 8
D28: Vek žiadateľa č.4 na limity | F28: =IF(F27="",0,IF(AND(DAY(F3)=DAY(F27),MONTH(F3)=MONTH(F27)),YEAR(F3)-YEAR(F27),FLOOR(YEARFRAC(F27,F3,1),1))) -> 0
D29: Počet žiadatelmi vyživovaných osôb
D30: Number of dependants with applicants | F30: =$F$20+$F$29 -> 1
D31: v tom detí
D32: Available income (including household expenses) | F32: =MAX(0.95*(F7-MAX($F$34,$F$35)),0) -> 0 | I32: =MIN(MAX(0.95*(F7-MAX($F$34,$F$35)),0),F7*0.75) -> 0
D33: Expenses - according to Slovak law (COSTS) | F33: =IF($F$30=0,0,(284.13+MAX(($F$30-$F$31-1)*198.22+($F$31)*129.74-F9-F12-F15-F18,0)+$F$43)) -> 284.13
D34: Expenses - according to Slovak law (COSTS) + Housing cost | F34: =IF($F$30=0,0,($F$33+F10+F13+F16+F19)) -> 284.13
D35: Expenses - according to the Bank's model (KUGD) | F35: =IF($F$30=0,0,MAX($F$30*((185*($F$30^(-0.4)))^(1-0.4))*(($F$7/$F$30)^(0.4)),0)) -> 0
D39: Výška mesačných splátok splátkových úverov | F39: 0
D40: Limity kontokorentných úverov | F40: 0
D41: Limity kreditných kariet | F41: 0
D42: Výška mesačných splátok alimentov, exekúcií a iných záväzkov | F42: 0
D43: Prepočtená výška mesačných splátok alimentov, exekúcií a iných záväzkov | F43: =IF($F$42=0,0,IF($F$42>30,$F$42,30)) -> 0
D44: Free income (including liabilities) | F44: =MAX((MIN($F$32,0.75*F7)-$F$39-0.03*$F$40-0.03*$F$41),0) -> 0
D48: Žiadaná čiastka úveru v EUR | F48: 0
...

Sheet RPSN
A2: anuita | K2: klesajuce
B3: vyska uveru | C3: ='prijem - EUR'!F49 -> 0 | L3: vyska uveru | M3: ='prijem - EUR'!F49 -> 0
B4: sadzba | C4: =urokova_sadzba -> 0 | L4: sadzba | M4: =urokova_sadzba -> 0
B5: splatnost | C5: =doba_m -> 0 | L5: splatnost | M5: =doba_m -> 0
B6: cena ZP | C6: ='prijem - EUR'!F53+'prijem - EUR'!F60+'prijem - EUR'!F67 -> 0 | L6: cena ZP | M6: ='prijem - EUR'!F53+'prijem - EUR'!F60+'prijem - EUR'!F67 -> 0
B7: poistné za rok | C7: ='prijem - EUR'!F54+'prijem - EUR'!F61+'prijem - EUR'!F68 -> 0 | L7: poistné za rok | M7: ='prijem - EUR'!F54+'prijem - EUR'!F61+'prijem - EUR'!F68 -> 0
B8: poistné za celú dobu | C8: ='prijem - EUR'!F55+'prijem - EUR'!F62+'prijem - EUR'!F69 -> 0 | L8: poistné za celú dobu | M8: ='prijem - EUR'!F55+'prijem - EUR'!F62+'prijem - EUR'!F69 -> 0
B9: vklad do katastru | C9: ='prijem - EUR'!E122+'prijem - EUR'!E123+'prijem - EUR'!E124 -> 0 | L9: vklad do katastru | M9: ='prijem - EUR'!E122+'prijem - EUR'!E123+'prijem - EUR'!E124 -> 0
B10: LCI | C10: =LCI -> #REF! | L10: LCI | M10: =LCI -> #REF!
B11: Life | C11: ='prijem - EUR'!F87 -> 0 | L11: Life | M11: ='prijem - EUR'!F87 -> 0
B12: RPSN | C12: =(1+IRR(B16:B496,1%))^12-1 -> #VALUE! | L12: RPSN | M12: =(1+IRR(L16:L496,1%))^12-1 -> #VALUE!
B13: celkova zaplatena | C13: =(SUM(B17:B496)*-1)+C6+C8+C9+H17 -> #NUM! | L13: celkova zaplatena | M13: =(SUM(L17:L496)*-1)+M6+M8+M9+R17 -> #DIV/0!
B15: CF | C15: zostatok | L15: CF | M15: zostatok
A16: mesiac | B16: =C3-C6-C7-C9-C11-H17 -> 0 | C16: =C3 -> 0 | D16: istina | E16: urok | F16: splatka | G16: splatka LI | H16: LI nezapoč | K16: mesiac | L16: =M3-M6-M7-M9-M11-R17 -> 0 | M16: =M3 -> 0 | N16: istina | O16: urok | P16: splatka | Q16: splatka LI | R16: LI nezapoč
A17: 1 | B17: =IF(C16>0.00001,F17-G17,0) -> 0 | C17: =MAX(C16-D17,0) -> #NUM! | D17: =(F17-E17)*-1 -> #NUM! | E17: =IPMT($C$4/12,1,$C$5,C16) -> #NUM! | F17: =PMT($C$4/12,$C$5,$C$3) -> #NUM! | H17: ='prijem - EUR'!F88 -> 0 | K17: 1 | L17: =IF(M16>0.00001,P17-Q17,0)*-1 -> 0 | M17: =MAX(M16-N17,0) -> #DIV/0! | N17: =$M$16/$M$5 -> #DIV/0! | O17: =M16*$M$4/12 -> 0 | P17: =O17+N17 -> #DIV/0! | R17: ='prijem - EUR'!F88 -> 0
A18: 2 | B18: =IF(C17>0.00001,F18-G18,0) -> #NUM! | C18: =MAX(C17-D18,0) -> #NUM! | D18: =(F18-E18)*-1 -> #NUM! | E18: =IPMT($C$4/12,1,$C$5,C17) -> #NUM! | F18: =PMT($C$4/12,$C$5,$C$3) -> #NUM! | K18: 2 | L18: =IF(M17>0.00001,P18-Q18,0)*-1 -> #DIV/0! | M18: =MAX(M17-N18,0) -> #DIV/0! | N18: =$M$16/$M$5 -> #DIV/0! | O18: =M17*$M$4/12 -> #DIV/0! | P18: =O18+N18 -> #DIV/0!
A19: 3 | B19: =IF(C18>0.00001,F19-G19,0) -> #NUM! | C19: =MAX(C18-D19,0) -> #NUM! | D19: =(F19-E19)*-1 -> #NUM! | E19: =IPMT($C$4/12,1,$C$5,C18) -> #NUM! | F19: =PMT($C$4/12,$C$5,$C$3) -> #NUM! | K19: 3 | L19: =IF(M18>0.00001,P19-Q19,0)*-1 -> #DIV/0! | M19: =MAX(M18-N19,0) -> #DIV/0! | N19: =$M$16/$M$5 -> #DIV/0! | O19: =M18*$M$4/12 -> #DIV/0! | P19: =O19+N19 -> #DIV/0!
A20: 4 | B20: =IF(C19>0.00001,F20-G20,0) -> #NUM! | C20: =MAX(C19-D20,0) -> #NUM! | D20: =(F20-E20)*-1 -> #NUM! | E20: =IPMT($C$4/12,1,$C$5,C19) -> #NUM! | F20: =PMT($C$4/12,$C$5,$C$3) -> #NUM! | K20: 4 | L20: =IF(M19>0.00001,P20-Q20,0)*-1 -> #DIV/0! | M20: =MAX(M19-N20,0) -> #DIV/0! | N20: =$M$16/$M$5 -> #DIV/0! | O20: =M19*$M$4/12 -> #DIV/0! | P20: =O20+N20 -> #DIV/0!
A21: 5 | B21: =IF(C20>0.00001,F21-G21,0) -> #NUM! | C21: =MAX(C20-D21,0) -> #NUM! | D21: =(F21-E21)*-1 -> #NUM! | E21: =IPMT($C$4/12,1,$C$5,C20) -> #NUM! | F21: =PMT($C$4/12,$C$5,$C$3) -> #NUM! | K21: 5 | L21: =IF(M20>0.00001,P21-Q21,0)*-1 -> #DIV/0! | M21: =MAX(M20-N21,0) -> #DIV/0! | N21: =$M$16/$M$5 -> #DIV/0! | O21: =M20*$M$4/12 -> #DIV/0! | P21: =O21+N21 -> #DIV/0!
A22: 6 | B22: =IF(C21>0.00001,F22-G22,0) -> #NUM! | C22: =MAX(C21-D22,0) -> #NUM! | D22: =(F22-E22)*-1 -> #NUM! | E22: =IPMT($C$4/12,1,$C$5,C21) -> #NUM! | F22: =PMT($C$4/12,$C$5,$C$3) -> #NUM! | K22: 6 | L22: =IF(M21>0.00001,P22-Q22,0)*-1 -> #DIV/0! | M22: =MAX(M21-N22,0) -> #DIV/0! | N22: =$M$16/$M$5 -> #DIV/0! | O22: =M21*$M$4/12 -> #DIV/0! | P22: =O22+N22 -> #DIV/0!
A23: 7 | B23: =IF(C22>0.00001,F23-G23,0) -> #NUM! | C23: =MAX(C22-D23,0) -> #NUM! | D23: =(F23-E23)*-1 -> #NUM! | E23: =IPMT($C$4/12,1,$C$5,C22) -> #NUM! | F23: =PMT($C$4/12,$C$5,$C$3) -> #NUM! | K23: 7 | L23: =IF(M22>0.00001,P23-Q23,0)*-1 -> #DIV/0! | M23: =MAX(M22-N23,0) -> #DIV/0! | N23: =$M$16/$M$5 -> #DIV/0! | O23: =M22*$M$4/12 -> #DIV/0! | P23: =O23+N23 -> #DIV/0!
A24: 8 | B24: =IF(C23>0.00001,F24-G24,0) -> #NUM! | C24: =MAX(C23-D24,0) -> #NUM! | D24: =(F24-E24)*-1 -> #NUM! | E24: =IPMT($C$4/12,1,$C$5,C23) -> #NUM! | F24: =PMT($C$4/12,$C$5,$C$3) -> #NUM! | K24: 8 | L24: =IF(M23>0.00001,P24-Q24,0)*-1 -> #DIV/0! | M24: =MAX(M23-N24,0) -> #DIV/0! | N24: =$M$16/$M$5 -> #DIV/0! | O24: =M23*$M$4/12 -> #DIV/0! | P24: =O24+N24 -> #DIV/0!
A25: 9 | B25: =IF(C24>0.00001,F25-G25,0) -> #NUM! | C25: =MAX(C24-D25,0) -> #NUM! | D25: =(F25-E25)*-1 -> #NUM! | E25: =IPMT($C$4/12,1,$C$5,C24) -> #NUM! | F25: =PMT($C$4/12,$C$5,$C$3) -> #NUM! | K25: 9 | L25: =IF(M24>0.00001,P25-Q25,0)*-1 -> #DIV/0! | M25: =MAX(M24-N25,0) -> #DIV/0! | N25: =$M$16/$M$5 -> #DIV/0! | O25: =M24*$M$4/12 -> #DIV/0! | P25: =O25+N25 -> #DIV/0!
A26: 10 | B26: =IF(C25>0.00001,F26-G26,0) -> #NUM! | C26: =MAX(C25-D26,0) -> #NUM! | D26: =(F26-E26)*-1 -> #NUM! | E26: =IPMT($C$4/12,1,$C$5,C25) -> #NUM! | F26: =PMT($C$4/12,$C$5,$C$3) -> #NUM! | K26: 10 | L26: =IF(M25>0.00001,P26-Q26,0)*-1 -> #DIV/0! | M26: =MAX(M25-N26,0) -> #DIV/0! | N26: =$M$16/$M$5 -> #DIV/0! | O26: =M25*$M$4/12 -> #DIV/0! | P26: =O26+N26 -> #DIV/0!
A27: 11 | B27: =IF(C26>0.00001,F27-G27,0) -> #NUM! | C27: =MAX(C26-D27,0) -> #NUM! | D27: =(F27-E27)*-1 -> #NUM! | E27: =IPMT($C$4/12,1,$C$5,C26) -> #NUM! | F27: =PMT($C$4/12,$C$5,$C$3) -> #NUM! | K27: 11 | L27: =IF(M26>0.00001,P27-Q27,0)*-1 -> #DIV/0! | M27: =MAX(M26-N27,0) -> #DIV/0! | N27: =$M$16/$M$5 -> #DIV/0! | O27: =M26*$M$4/12 -> #DIV/0! | P27: =O27+N27 -> #DIV/0!
A28: 12 | B28: =IF(C27>0.00001,F28-G28,0) -> #NUM! | C28: =MAX(C27-D28,0) -> #NUM! | D28: =(F28-E28)*-1 -> #NUM! | E28: =IPMT($C$4/12,1,$C$5,C27) -> #NUM! | F28: =PMT($C$4/12,$C$5,$C$3) -> #NUM! | K28: 12 | L28: =IF(M27>0.00001,P28-Q28,0)*-1 -> #DIV/0! | M28: =MAX(M27-N28,0) -> #DIV/0! | N28: =$M$16/$M$5 -> #DIV/0! | O28: =M27*$M$4/12 -> #DIV/0! | P28: =O28+N28 -> #DIV/0!
A29: 13 | B29: =IF(C28>0.00001,F29-G29,0) -> #NUM! | C29: =MAX(C28-D29,0) -> #NUM! | D29: =(F29-E29)*-1 -> #NUM! | E29: =IPMT($C$4/12,1,$C$5,C28) -> #NUM! | F29: =PMT($C$4/12,$C$5,$C$3) -> #NUM! | K29: 13 | L29: =IF(M28>0.00001,P29-Q29,0)*-1 -> #DIV/0! | M29: =MAX(M28-N29,0) -> #DIV/0! | N29: =$M$16/$M$5 -> #DIV/0! | O29: =M28*$M$4/12 -> #DIV/0! | P29: =O29+N29 -> #DIV/0!
... A40: 24 | B40: =IF(C39>0.00001,F40-G40,0) -> #NUM! | C40: =MAX(C39-D40,0) -> #NUM! | D40: =(F40-E40)*-1 -> #NUM! | E40: =IPMT($C$4/12,1,$C$5,C39) -> #NUM! | F40: =PMT($C$4/12,$C$5,$C$3) -> #NUM! | K40: 24 | L40: =IF(M39>0.00001,P40-Q40,0)*-1 -> #DIV/0! | M40: =MAX(M39-N40,0) -> #DIV/0! | N40: =$M$16/$M$5 -> #DIV/0! | O40: =M39*$M$4/12 -> #DIV/0! | P40: =O40+N40 -> #DIV/0!
A41: 25 | B41: =IF(C40>0.00001,F41-G41,0) -> #NUM! | C41: =MAX(C40-D41,0) -> #NUM! | D41: =(F41-E41)*-1 -> #NUM! | E41: =IPMT($C$4/12,1,$C$5,C40) -> #NUM! | F41: =PMT($C$4/12,$C$5,$C$3) -> #NUM! | G41: =IF('prijem - EUR'!$I$87=TRUE,IF($C$11>0,0.00025*C40,0),IF('prijem - EUR'!$I$88=TRUE,IF('prijem - EUR'!$F$88>0,0.00025*C40,0),0)) -> 0 | K41: 25 | L41: =IF(M40>0.00001,P41-Q41,0)*-1 -> #DIV/0! | M41: =MAX(M40-N41,0) -> #DIV/0! | N41: =$M$16/$M$5 -> #DIV/0! | O41: =M40*$M$4/12 -> #DIV/0! | P41: =O41+N41 -> #DIV/0! | Q41: =IF('prijem - EUR'!$I$87=TRUE,IF($C$11>0,0.00025*M40,0),IF('prijem - EUR'!$I$88=TRUE,IF('prijem - EUR'!$F$88>0,0.00025*M40*-1,0),0)) -> 0
A42: 26 | B42: =IF(C41>0.00001,F42-G42,0) -> #NUM! | C42: =MAX(C41-D42,0) -> #NUM! | D42: =(F42-E42)*-1 -> #NUM! | E42: =IPMT($C$4/12,1,$C$5,C41) -> #NUM! | F42: =PMT($C$4/12,$C$5,$C$3) -> #NUM! | G42: =IF('prijem - EUR'!$I$87=TRUE,IF($C$11>0,0.00025*C41,0),IF('prijem - EUR'!$I$88=TRUE,IF('prijem - EUR'!$F$88>0,0.00025*C41,0),0)) -> 0 | K42: 26 | L42: =IF(M41>0.00001,P42-Q42,0)*-1 -> #DIV/0! | M42: =MAX(M41-N42,0) -> #DIV/0! | N42: =$M$16/$M$5 -> #DIV/0! | O42: =M41*$M$4/12 -> #DIV/0! | P42: =O42+N42 -> #DIV/0! | Q42: =IF('prijem - EUR'!$I$87=TRUE,IF($C$11>0,0.00025*M41,0),IF('prijem - EUR'!$I$88=TRUE,IF('prijem - EUR'!$F$88>0,0.00025*M41*-1,0),0)) -> 0
A43: 27 | B43: =IF(C42>0.00001,F43-G43,0) -> #NUM! | C43: =MAX(C42-D43,0) -> #NUM! | D43: =(F43-E43)*-1 -> #NUM! | E43: =IPMT($C$4/12,1,$C$5,C42) -> #NUM! | F43: =PMT($C$4/12,$C$5,$C$3) -> #NUM! | G43: =IF('prijem - EUR'!$I$87=TRUE,IF($C$11>0,0.00025*C42,0),IF('prijem - EUR'!$I$88=TRUE,IF('prijem - EUR'!$F$88>0,0.00025*C42,0),0)) -> 0 | K43: 27 | L43: =IF(M42>0.00001,P43-Q43,0)*-1 -> #DIV/0! | M43: =MAX(M42-N43,0) -> #DIV/0! | N43: =$M$16/$M$5 -> #DIV/0! | O43: =M42*$M$4/12 -> #DIV/0! | P43: =O43+N43 -> #DIV/0! | Q43: =IF('prijem - EUR'!$I$87=TRUE,IF($C$11>0,0.00025*M42,0),IF('prijem - EUR'!$I$88=TRUE,IF('prijem - EUR'!$F$88>0,0.00025*M42*-1,0),0)) -> 0
A44: 28 | B44: =IF(C43>0.00001,F44-G44,0) -> #NUM! | C44: =MAX(C43-D44,0) -> #NUM! | D44: =(F44-E44)*-1 -> #NUM! | E44: =IPMT($C$4/12,1,$C$5,C43) -> #NUM! | F44: =PMT($C$4/12,$C$5,$C$3) -> #NUM! | G44: =IF('prijem - EUR'!$I$87=TRUE,IF($C$11>0,0.00025*C43,0),IF('prijem - EUR'!$I$88=TRUE,IF('prijem - EUR'!$F$88>0,0.00025*C43,0),0)) -> 0 | K44: 28 | L44: =IF(M43>0.00001,P44-Q44,0)*-1 -> #DIV/0! | M44: =MAX(M43-N44,0) -> #DIV/0! | N44: =$M$16/$M$5 -> #DIV/0! | O44: =M43*$M$4/12 -> #DIV/0! | P44: =O44+N44 -> #DIV/0! | Q44: =IF('prijem - EUR'!$I$87=TRUE,IF($C$11>0,0.00025*M43,0),IF('prijem - EUR'!$I$88=TRUE,IF('prijem - EUR'!$F$88>0,0.00025*M43*-1,0),0)) -> 0
A45: 29 | B45: =IF(C44>0.00001,F45-G45,0) -> #NUM! | C45: =MAX(C44-D45,0) -> #NUM! | D45: =(F45-E45)*-1 -> #NUM! | E45: =IPMT($C$4/12,1,$C$5,C44) -> #NUM! | F45: =PMT($C$4/12,$C$5,$C$3) -> #NUM! | G45: =IF('prijem - EUR'!$I$87=TRUE,IF($C$11>0,0.00025*C44,0),IF('prijem - EUR'!$I$88=TRUE,IF('prijem - EUR'!$F$88>0,0.00025*C44,0),0)) -> 0 | K45: 29 | L45: =IF(M44>0.00001,P45-Q45,0)*-1 -> #DIV/0! | M45: =MAX(M44-N45,0) -> #DIV/0! | N45: =$M$16/$M$5 -> #DIV/0! | O45: =M44*$M$4/12 -> #DIV/0! | P45: =O45+N45 -> #DIV/0! | Q45: =IF('prijem - EUR'!$I$87=TRUE,IF($C$11>0,0.00025*M44,0),IF('prijem - EUR'!$I$88=TRUE,IF('prijem - EUR'!$F$88>0,0.00025*M44*-1,0),0)) -> 0
A46: 30 | B46: =IF(C45>0.00001,F46-G46,0) -> #NUM! | C46: =MAX(C45-D46,0) -> #NUM! | D46: =(F46-E46)*-1 -> #NUM! | E46: =IPMT($C$4/12,1,$C$5,C45) -> #NUM! | F46: =PMT($C$4/12,$C$5,$C$3) -> #NUM! | G46: =IF('prijem - EUR'!$I$87=TRUE,IF($C$11>0,0.00025*C45,0),IF('prijem - EUR'!$I$88=TRUE,IF('prijem - EUR'!$F$88>0,0.00025*C45,0),0)) -> 0 | K46: 30 | L46: =IF(M45>0.00001,P46-Q46,0)*-1 -> #DIV/0! | M46: =MAX(M45-N46,0) -> #DIV/0! | N46: =$M$16/$M$5 -> #DIV/0! | O46: =M45*$M$4/12 -> #DIV/0! | P46: =O46+N46 -> #DIV/0! | Q46: =IF('prijem - EUR'!$I$87=TRUE,IF($C$11>0,0.00025*M45,0),IF('prijem - EUR'!$I$88=TRUE,IF('prijem - EUR'!$F$88>0,0.00025*M45*-1,0),0)) -> 0
A47: 31 | B47: =IF(C46>0.00001,F47-G47,0) -> #NUM! | C47: =MAX(C46-D47,0) -> #NUM! | D47: =(F47-E47)*-1 -> #NUM! | E47: =IPMT($C$4/12,1,$C$5,C46) -> #NUM! | F47: =PMT($C$4/12,$C$5,$C$3) -> #NUM! | G47: =IF('prijem - EUR'!$I$87=TRUE,IF($C$11>0,0.00025*C46,0),IF('prijem - EUR'!$I$88=TRUE,IF('prijem - EUR'!$F$88>0,0.00025*C46,0),0)) -> 0 | K47: 31 | L47: =IF(M46>0.00001,P47-Q47,0)*-1 -> #DIV/0! | M47: =MAX(M46-N47,0) -> #DIV/0! | N47: =$M$16/$M$5 -> #DIV/0! | O47: =M46*$M$4/12 -> #DIV/0! | P47: =O47+N47 -> #DIV/0! | Q47: =IF('prijem - EUR'!$I$87=TRUE,IF($C$11>0,0.00025*M46,0),IF('prijem - EUR'!$I$88=TRUE,IF('prijem - EUR'!$F$88>0,0.00025*M46*-1,0),0)) -> 0
A48: 32 | B48: =IF(C47>0.00001,F48-G48,0) -> #NUM! | C48: =MAX(C47-D48,0) -> #NUM! | D48: =(F48-E48)*-1 -> #NUM! | E48: =IPMT($C$4/12,1,$C$5,C47) -> #NUM! | F48: =PMT($C$4/12,$C$5,$C$3) -> #NUM! | G48: =IF('prijem - EUR'!$I$87=TRUE,IF($C$11>0,0.00025*C47,0),IF('prijem - EUR'!$I$88=TRUE,IF('prijem - EUR'!$F$88>0,0.00025*C47,0),0)) -> 0 | K48: 32 | L48: =IF(M47>0.00001,P48-Q48,0)*-1 -> #DIV/0! | M48: =MAX(M47-N48,0) -> #DIV/0! | N48: =$M$16/$M$5 -> #DIV/0! | O48: =M47*$M$4/12 -> #DIV/0! | P48: =O48+N48 -> #DIV/0! | Q48: =IF('prijem - EUR'!$I$87=TRUE,IF($C$11>0,0.00025*M47,0),IF('prijem - EUR'!$I$88=TRUE,IF('prijem - EUR'!$F$88>0,0.00025*M47*-1,0),0)) -> 0
A49: 33 | B49: =IF(C48>0.00001,F49-G49,0) -> #NUM! | C49: =MAX(C48-D49,0) -> #NUM! | D49: =(F49-E49)*-1 -> #NUM! | E49: =IPMT($C$4/12,1,$C$5,C48) -> #NUM! | F49: =PMT($C$4/12,$C$5,$C$3) -> #NUM! | G49: =IF('prijem - EUR'!$I$87=TRUE,IF($C$11>0,0.00025*C48,0),IF('prijem - EUR'!$I$88=TRUE,IF('prijem - EUR'!$F$88>0,0.00025*C48,0),0)) -> 0 | K49: 33 | L49: =IF(M48>0.00001,P49-Q49,0)*-1 -> #DIV/0! | M49: =MAX(M48-N49,0) -> #DIV/0! | N49: =$M$16/$M$5 -> #DIV/0! | O49: =M48*$M$4/12 -> #DIV/0! | P49: =O49+N49 -> #DIV/0! | Q49: =IF('prijem - EUR'!$I$87=TRUE,IF($C$11>0,0.00025*M48,0),IF('prijem - EUR'!$I$88=TRUE,IF('prijem - EUR'!$F$88>0,0.00025*M48*-1,0),0)) -> 0
A50: 34 | B50: =IF(C49>0.00001,F50-G50,0) -> #NUM! | C50: =MAX(C49-D50,0) -> #NUM! | D50: =(F50-E50)*-1 -> #NUM! | E50: =IPMT($C$4/12,1,$C$5,C49) -> #NUM! | F50: =PMT($C$4/12,$C$5,$C$3) -> #NUM! | G50: =IF('prijem - EUR'!$I$87=TRUE,IF($C$11>0,0.00025*C49,0),IF('prijem - EUR'!$I$88=TRUE,IF('prijem - EUR'!$F$88>0,0.00025*C49,0),0)) -> 0 | K50: 34 | L50: =IF(M49>0.00001,P50-Q50,0)*-1 -> #DIV/0! | M50: =MAX(M49-N50,0) -> #DIV/0! | N50: =$M$16/$M$5 -> #DIV/0! | O50: =M49*$M$4/12 -> #DIV/0! | P50: =O50+N50 -> #DIV/0! | Q50: =IF('prijem - EUR'!$I$87=TRUE,IF($C$11>0,0.00025*M49,0),IF('prijem - EUR'!$I$88=TRUE,IF('prijem - EUR'!$F$88>0,0.00025*M49*-1,0),0)) -> 0
A51: 35 | B51: =IF(C50>0.00001,F51-G51,0) -> #NUM! | C51: =MAX(C50-D51,0) -> #NUM! | D51: =(F51-E51)*-1 -> #NUM! | E51: =IPMT($C$4/12,1,$C$5,C50) -> #NUM! | F51: =PMT($C$4/12,$C$5,$C$3) -> #NUM! | G51: =IF('prijem - EUR'!$I$87=TRUE,IF($C$11>0,0.00025*C50,0),IF('prijem - EUR'!$I$88=TRUE,IF('prijem - EUR'!$F$88>0,0.00025*C50,0),0)) -> 0 | K51: 35 | L51: =IF(M50>0.00001,P51-Q51,0)*-1 -> #DIV/0! | M51: =MAX(M50-N51,0) -> #DIV/0! | N51: =$M$16/$M$5 -> #DIV/0! | O51: =M50*$M$4/12 -> #DIV/0! | P51: =O51+N51 -> #DIV/0! | Q51: =IF('prijem - EUR'!$I$87=TRUE,IF($C$11>0,0.00025*M50,0),IF('prijem - EUR'!$I$88=TRUE,IF('prijem - EUR'!$F$88>0,0.00025*M50*-1,0),0)) -> 0
A52: 36 | B52: =IF(C51>0.00001,F52-G52,0) -> #NUM! | C52: =MAX(C51-D52,0) -> #NUM! | D52: =(F52-E52)*-1 -> #NUM! | E52: =IPMT($C$4/12,1,$C$5,C51) -> #NUM! | F52: =PMT($C$4/12,$C$5,$C$3) -> #NUM! | G52: =IF('prijem - EUR'!$I$87=TRUE,IF($C$11>0,0.00025*C51,0),IF('prijem - EUR'!$I$88=TRUE,IF('prijem - EUR'!$F$88>0,0.00025*C51,0),0)) -> 0 | K52: 36 | L52: =IF(M51>0.00001,P52-Q52,0)*-1 -> #DIV/0! | M52: =MAX(M51-N52,0) -> #DIV/0! | N52: =$M$16/$M$5 -> #DIV/0! | O52: =M51*$M$4/12 -> #DIV/0! | P52: =O52+N52 -> #DIV/0! | Q52: =IF('prijem - EUR'!$I$87=TRUE,IF($C$11>0,0.00025*M51,0),IF('prijem - EUR'!$I$88=TRUE,IF('prijem - EUR'!$F$88>0,0.00025*M51*-1,0),0)) -> 0
...

Sheet prijem -inna mena
C1: Kalkulačka mHypotéka
D3: Meno klienta
F4: =IF(ISBLANK(F3),"DÁTUM PODANIA!","OK") -> DÁTUM PODANIA!
D5: Číslo žiadosti
D7: Mesačný čistý príjem domácnosti v EUR (prepočtený dle veku) | F7: =F9+F11+F12+F14+F15+F17+F18+F20 -> 0
D8: Mesačný čistý príjem domácnosti v EUR (neprepočtený dle veku) | F8: =F10+F11+F13+F14+F16+F17+F19+F20 -> 0
D9: Čistý príjem žiadateľa č.1 zo závislej činnosti alebo živnosti | F9: =IF(F24="","0",(F10*(F55-MIN(MAX(F24+F55-744,0),F55))/F55)+(F10*0.85*MIN(MAX(F24+F55-744,0),F55)/F55)) -> 0
D10: Čistý príjem žiadateľa č.1 doba určitá/ neurčitá/dohoda/zahraničie
D11: Čistý príjem žiadateľa č.1 z inej činnosti | F11: 0
D12: Čistý príjem žiadateľa č.2 zo závislej činnosti alebo živnosti | F12: =IF(F27="","0",(F13*(F55-MIN(MAX(F27+F55-744,0),F55))/F55)+(F13*0.85*MIN(MAX(F27+F55-744,0),F55)/F55)) -> 0
D13: Čistý príjem žiadateľa č.2 doba určitá/ neurčitá/dohoda/zahraničie
D14: Čistý príjem žiadateľa č.2 z inej činnosti
D15: Čistý príjem žiadateľa č.3 zo závislej činnosti alebo živnosti | F15: =IF(F30="","0",(F16*(F55-MIN(MAX(F30+F55-744,0),F55))/F55)+(F16*0.85*MIN(MAX(F30+F55-744,0),F55)/F55)) -> 0
D16: Čistý príjem žiadateľa č.3 doba určitá/ neurčitá/dohoda/zahraničie
D17: Čistý príjem žiadateľa č.3 z inej činnosti
D18: Čistý príjem žiadateľa č.4 zo závislej činnosti alebo živnosti | F18: =IF(F33="","0",(F19*(F55-MIN(MAX(F33+F55-744,0),F55))/F55)+(F19*0.85*MIN(MAX(F33+F55-744,0),F55)/F55)) -> 0
D19: Čistý príjem žiadateľa č.4 doba určitá/ neurčitá/dohoda/zahraničie
D20: Čistý príjem žiadateľa č.4 z inej činnosti
D21: Počet žiadatelov | F21: 0
D22: Dátum narodenia žiadateľa č. 1
D23: Vek žiadateľa č.1 na limity | F23: =IF(F22="","",YEAR(F3)-YEAR(F22))
D24: Vek žiadateľa č.1 v mesiacoch | F24: =IF(F22="","",(DATEDIF(F22,F3,"M"))+(IF((DAY(F22)-DAY(F3))<=0,0,1)))
D25: Dátum narodenia žiadateľa č. 2
D26: Vek žiadateľa č.2 na limity | F26: =IF(F25="","",YEAR(F3)-YEAR(F25))
D27: Vek žiadateľa č.2 v mesiacoch | F27: =IF(F25="","",(DATEDIF(F25,F3,"M"))+(IF((DAY(F25)-DAY(F3))<=0,0,1)))
D28: Dátum narodenia žiadateľa č. 3
D29: Vek žiadateľa č.3 na limity | F29: =IF(F28="","",YEAR(F3)-YEAR(F28))
D30: Vek žiadateľa č.3 v mesiacoch | F30: =IF(F28="","",(DATEDIF(F28,F3,"M"))+(IF((DAY(F28)-DAY(F3))<=0,0,1)))
D31: Dátum narodenia žiadateľa č. 4
D32: Vek žiadateľa č.4 na limity | F32: =IF(F31="","",YEAR(F3)-YEAR(F31))
D33: Vek žiadateľa č.4 v mesiacoch | F33: =IF(F31="","",(DATEDIF(F31,F3,"M"))+(IF((DAY(F31)-DAY(F3))<=0,0,1)))
D34: Počet žiadatelmi vyživovaných osôb | F34: 0
D35: Number of dependants with applicants | F35: =$F$21+$F$34 -> 0
D36: v tom detí | F36: 0
D37: Available income (including household expenses) | F37: =MAX(0.95*(F7-MAX($F$38,$F$39)),0) -> 0
D38: Expenses - according to Slovak law (COSTS) | F38: =IF($F$35=0,0,0.2*(F7-(210.2+($F$35-$F$36-1)*146.64+($F$36)*95.96+$F$48))+(210.2+($F$35-$F$36-1)*146.64+($F$36)*95.96+$F$48)) -> 0
D39: Expenses - according to the Bank's model (KUGD) | F39: =IF($F$35=0,0,$F$35*((185*($F$35^(-0.4)))^(1-0.4))*(($F$8/$F$35)^(0.4))) -> 0
D43: Výška mesačných splátok splátkových úverov v mBank | F43: 0
D44: Výška mesačných splátok splátkových úverov v iných bankách | F44: 0
D45: Limity kontokorentných úverov | F45: 0
...

Sheet RPSN_zahranicie
A2: anuita | L2: klesajuce
B3: vyska uveru | C3: ='prijem -inna mena'!F54 -> 0 | M3: vyska uveru | N3: ='prijem -inna mena'!F54 -> 0
B4: sadzba | C4: =urokova_sadzba_z -> 0 | M4: sadzba | N4: =urokova_sadzba_z -> 0
B5: splatnost | C5: =doba_m_z -> 0 | M5: splatnost | N5: =doba_m_z -> 0
B6: cena ZP | C6: ='prijem -inna mena'!F58+'prijem -inna mena'!F65+'prijem -inna mena'!F72 -> 0 | M6: cena ZP | N6: ='prijem -inna mena'!F58+'prijem -inna mena'!F65+'prijem -inna mena'!F72 -> 0
B7: poistné za rok | C7: ='prijem -inna mena'!F59+'prijem -inna mena'!F66+'prijem -inna mena'!F73 -> 0 | M7: poistné za rok | N7: ='prijem -inna mena'!F59+'prijem -inna mena'!F66+'prijem -inna mena'!F73 -> 0
B8: poistné za celú dobu | C8: ='prijem -inna mena'!F60+'prijem -inna mena'!F67+'prijem -inna mena'!F74 -> 0 | M8: poistné za celú dobu | N8: ='prijem -inna mena'!F60+'prijem -inna mena'!F67+'prijem -inna mena'!F74 -> 0
B9: vklad do katastru | C9: ='prijem -inna mena'!E107+'prijem -inna mena'!E108+'prijem -inna mena'!E109 -> 0 | M9: vklad do katastru | N9: ='prijem -inna mena'!E107+'prijem -inna mena'!E108+'prijem -inna mena'!E109 -> 0
B10: LCI | C10: =LCI_z -> #REF! | M10: LCI | N10: =LCI_z -> #REF!
B11: Life | C11: ='prijem -inna mena'!F90 -> 0 | M11: Life | N11: ='prijem -inna mena'!F90 -> 0
B12: RPSN | C12: =(1+IRR(B16:B496,1%))^12-1 -> #VALUE! | M12: RPSN | N12: =(1+IRR(M16:M496,1%))^12-1 -> #VALUE!
B13: celkova zaplatena | C13: =(SUM(B17:B496)*-1)+C6+C8+C9+H17 -> #NUM! | M13: celkova zaplatena | N13: =(SUM(M17:M496)*-1)+N6+N8+N9+S17 -> #DIV/0!
B15: CF | C15: zostatok | M15: CF | N15: zostatok
A16: mesiac | B16: =C3-C6-C7-C9-C11-H17 -> 0 | C16: =C3 -> 0 | D16: istina | E16: urok | F16: splatka | G16: splatka LI | H16: LI nezapoč | L16: mesiac | M16: =N3-N6-N7-N9-N11-S17 -> 0 | N16: =N3 -> 0 | O16: istina | P16: urok | Q16: splatka | R16: splatka LI | S16: LI nezapoč
A17: 1 | B17: =IF(C16>0.00001,F17-G17,0) -> 0 | C17: =MAX(C16-D17,0) -> #NUM! | D17: =(F17-E17)*-1 -> #NUM! | E17: =IPMT($C$4/12,1,$C$5,C16) -> #NUM! | F17: =PMT($C$4/12,$C$5,$C$3) -> #NUM! | H17: ='prijem -inna mena'!F91 -> 0 | L17: 1 | M17: =IF(N16>0.00001,Q17-R17,0)*-1 -> 0 | N17: =MAX(N16-O17,0) -> #DIV/0! | O17: =$N$16/$N$5 -> #DIV/0! | P17: =N16*$N$4/12 -> 0 | Q17: =P17+O17 -> #DIV/0! | S17: ='prijem -inna mena'!F91 -> 0
A18: 2 | B18: =IF(C17>0.00001,F18-G18,0) -> #NUM! | C18: =MAX(C17-D18,0) -> #NUM! | D18: =(F18-E18)*-1 -> #NUM! | E18: =IPMT($C$4/12,1,$C$5,C17) -> #NUM! | F18: =PMT($C$4/12,$C$5,$C$3) -> #NUM! | L18: 2 | M18: =IF(N17>0.00001,Q18-R18,0)*-1 -> #DIV/0! | N18: =MAX(N17-O18,0) -> #DIV/0! | O18: =$N$16/$N$5 -> #DIV/0! | P18: =N17*$N$4/12 -> #DIV/0! | Q18: =P18+O18 -> #DIV/0!
A19: 3 | B19: =IF(C18>0.00001,F19-G19,0) -> #NUM! | C19: =MAX(C18-D19,0) -> #NUM! | D19: =(F19-E19)*-1 -> #NUM! | E19: =IPMT($C$4/12,1,$C$5,C18) -> #NUM! | F19: =PMT($C$4/12,$C$5,$C$3) -> #NUM! | L19: 3 | M19: =IF(N18>0.00001,Q19-R19,0)*-1 -> #DIV/0! | N19: =MAX(N18-O19,0) -> #DIV/0! | O19: =$N$16/$N$5 -> #DIV/0! | P19: =N18*$N$4/12 -> #DIV/0! | Q19: =P19+O19 -> #DIV/0!
A20: 4 | B20: =IF(C19>0.00001,F20-G20,0) -> #NUM! | C20: =MAX(C19-D20,0) -> #NUM! | D20: =(F20-E20)*-1 -> #NUM! | E20: =IPMT($C$4/12,1,$C$5,C19) -> #NUM! | F20: =PMT($C$4/12,$C$5,$C$3) -> #NUM! | L20: 4 | M20: =IF(N19>0.00001,Q20-R20,0)*-1 -> #DIV/0! | N20: =MAX(N19-O20,0) -> #DIV/0! | O20: =$N$16/$N$5 -> #DIV/0! | P20: =N19*$N$4/12 -> #DIV/0! | Q20: =P20+O20 -> #DIV/0!
A21: 5 | B21: =IF(C20>0.00001,F21-G21,0) -> #NUM! | C21: =MAX(C20-D21,0) -> #NUM! | D21: =(F21-E21)*-1 -> #NUM! | E21: =IPMT($C$4/12,1,$C$5,C20) -> #NUM! | F21: =PMT($C$4/12,$C$5,$C$3) -> #NUM! | L21: 5 | M21: =IF(N20>0.00001,Q21-R21,0)*-1 -> #DIV/0! | N21: =MAX(N20-O21,0) -> #DIV/0! | O21: =$N$16/$N$5 -> #DIV/0! | P21: =N20*$N$4/12 -> #DIV/0! | Q21: =P21+O21 -> #DIV/0!
A22: 6 | B22: =IF(C21>0.00001,F22-G22,0) -> #NUM! | C22: =MAX(C21-D22,0) -> #NUM! | D22: =(F22-E22)*-1 -> #NUM! | E22: =IPMT($C$4/12,1,$C$5,C21) -> #NUM! | F22: =PMT($C$4/12,$C$5,$C$3) -> #NUM! | L22: 6 | M22: =IF(N21>0.00001,Q22-R22,0)*-1 -> #DIV/0! | N22: =MAX(N21-O22,0) -> #DIV/0! | O22: =$N$16/$N$5 -> #DIV/0! | P22: =N21*$N$4/12 -> #DIV/0! | Q22: =P22+O22 -> #DIV/0!
A23: 7 | B23: =IF(C22>0.00001,F23-G23,0) -> #NUM! | C23: =MAX(C22-D23,0) -> #NUM! | D23: =(F23-E23)*-1 -> #NUM! | E23: =IPMT($C$4/12,1,$C$5,C22) -> #NUM! | F23: =PMT($C$4/12,$C$5,$C$3) -> #NUM! | L23: 7 | M23: =IF(N22>0.00001,Q23-R23,0)*-1 -> #DIV/0! | N23: =MAX(N22-O23,0) -> #DIV/0! | O23: =$N$16/$N$5 -> #DIV/0! | P23: =N22*$N$4/12 -> #DIV/0! | Q23: =P23+O23 -> #DIV/0!
A24: 8 | B24: =IF(C23>0.00001,F24-G24,0) -> #NUM! | C24: =MAX(C23-D24,0) -> #NUM! | D24: =(F24-E24)*-1 -> #NUM! | E24: =IPMT($C$4/12,1,$C$5,C23) -> #NUM! | F24: =PMT($C$4/12,$C$5,$C$3) -> #NUM! | L24: 8 | M24: =IF(N23>0.00001,Q24-R24,0)*-1 -> #DIV/0! | N24: =MAX(N23-O24,0) -> #DIV/0! | O24: =$N$16/$N$5 -> #DIV/0! | P24: =N23*$N$4/12 -> #DIV/0! | Q24: =P24+O24 -> #DIV/0!
A25: 9 | B25: =IF(C24>0.00001,F25-G25,0) -> #NUM! | C25: =MAX(C24-D25,0) -> #NUM! | D25: =(F25-E25)*-1 -> #NUM! | E25: =IPMT($C$4/12,1,$C$5,C24) -> #NUM! | F25: =PMT($C$4/12,$C$5,$C$3) -> #NUM! | L25: 9 | M25: =IF(N24>0.00001,Q25-R25,0)*-1 -> #DIV/0! | N25: =MAX(N24-O25,0) -> #DIV/0! | O25: =$N$16/$N$5 -> #DIV/0! | P25: =N24*$N$4/12 -> #DIV/0! | Q25: =P25+O25 -> #DIV/0!
A26: 10 | B26: =IF(C25>0.00001,F26-G26,0) -> #NUM! | C26: =MAX(C25-D26,0) -> #NUM! | D26: =(F26-E26)*-1 -> #NUM! | E26: =IPMT($C$4/12,1,$C$5,C25) -> #NUM! | F26: =PMT($C$4/12,$C$5,$C$3) -> #NUM! | L26: 10 | M26: =IF(N25>0.00001,Q26-R26,0)*-1 -> #DIV/0! | N26: =MAX(N25-O26,0) -> #DIV/0! | O26: =$N$16/$N$5 -> #DIV/0! | P26: =N25*$N$4/12 -> #DIV/0! | Q26: =P26+O26 -> #DIV/0!
A27: 11 | B27: =IF(C26>0.00001,F27-G27,0) -> #NUM! | C27: =MAX(C26-D27,0) -> #NUM! | D27: =(F27-E27)*-1 -> #NUM! | E27: =IPMT($C$4/12,1,$C$5,C26) -> #NUM! | F27: =PMT($C$4/12,$C$5,$C$3) -> #NUM! | L27: 11 | M27: =IF(N26>0.00001,Q27-R27,0)*-1 -> #DIV/0! | N27: =MAX(N26-O27,0) -> #DIV/0! | O27: =$N$16/$N$5 -> #DIV/0! | P27: =N26*$N$4/12 -> #DIV/0! | Q27: =P27+O27 -> #DIV/0!
A28: 12 | B28: =IF(C27>0.00001,F28-G28,0) -> #NUM! | C28: =MAX(C27-D28,0) -> #NUM! | D28: =(F28-E28)*-1 -> #NUM! | E28: =IPMT($C$4/12,1,$C$5,C27) -> #NUM! | F28: =PMT($C$4/12,$C$5,$C$3) -> #NUM! | L28: 12 | M28: =IF(N27>0.00001,Q28-R28,0)*-1 -> #DIV/0! | N28: =MAX(N27-O28,0) -> #DIV/0! | O28: =$N$16/$N$5 -> #DIV/0! | P28: =N27*$N$4/12 -> #DIV/0! | Q28: =P28+O28 -> #DIV/0!
A29: 13 | B29: =IF(C28>0.00001,F29-G29,0) -> #NUM! | C29: =MAX(C28-D29,0) -> #NUM! | D29: =(F29-E29)*-1 -> #NUM! | E29: =IPMT($C$4/12,1,$C$5,C28) -> #NUM! | F29: =PMT($C$4/12,$C$5,$C$3) -> #NUM! | L29: 13 | M29: =IF(N28>0.00001,Q29-R29,0)*-1 -> #DIV/0! | N29: =MAX(N28-O29,0) -> #DIV/0! | O29: =$N$16/$N$5 -> #DIV/0! | P29: =N28*$N$4/12 -> #DIV/0! | Q29: =P29+O29 -> #DIV/0!
... A40: 24 | B40: =IF(C39>0.00001,F40-G40,0) -> #NUM! | C40: =MAX(C39-D40,0) -> #NUM! | D40: =(F40-E40)*-1 -> #NUM! | E40: =IPMT($C$4/12,1,$C$5,C39) -> #NUM! | F40: =PMT($C$4/12,$C$5,$C$3) -> #NUM! | L40: 24 | M40: =IF(N39>0.00001,Q40-R40,0)*-1 -> #DIV/0! | N40: =MAX(N39-O40,0) -> #DIV/0! | O40: =$N$16/$N$5 -> #DIV/0! | P40: =N39*$N$4/12 -> #DIV/0! | Q40: =P40+O40 -> #DIV/0!
A41: 25 | B41: =IF(C40>0.00001,F41-G41,0) -> #NUM! | C41: =MAX(C40-D41,0) -> #NUM! | D41: =(F41-E41)*-1 -> #NUM! | E41: =IPMT($C$4/12,1,$C$5,C40) -> #NUM! | F41: =PMT($C$4/12,$C$5,$C$3) -> #NUM! | G41: =IF('prijem -inna mena'!$I$90=TRUE,IF($C$11>0,0.00025*C40,0),IF('prijem -inna mena'!$I$91=TRUE,IF('prijem -inna mena'!$F$91>0,0.00025*C40,0),0)) -> 0 | L41: 25 | M41: =IF(N40>0.00001,Q41-R41,0)*-1 -> #DIV/0! | N41: =MAX(N40-O41,0) -> #DIV/0! | O41: =$N$16/$N$5 -> #DIV/0! | P41: =N40*$N$4/12 -> #DIV/0! | Q41: =P41+O41 -> #DIV/0! | R41: =IF('prijem -inna mena'!$I$90=TRUE,IF($C$11>0,0.00025*N40,0),IF('prijem -inna mena'!$I$91=TRUE,IF('prijem -inna mena'!$F$91>0,0.00025*N40*-1,0),0)) -> 0
A42: 26 | B42: =IF(C41>0.00001,F42-G42,0) -> #NUM! | C42: =MAX(C41-D42,0) -> #NUM! | D42: =(F42-E42)*-1 -> #NUM! | E42: =IPMT($C$4/12,1,$C$5,C41) -> #NUM! | F42: =PMT($C$4/12,$C$5,$C$3) -> #NUM! | G42: =IF('prijem -inna mena'!$I$90=TRUE,IF($C$11>0,0.00025*C41,0),IF('prijem -inna mena'!$I$91=TRUE,IF('prijem -inna mena'!$F$91>0,0.00025*C41,0),0)) -> 0 | L42: 26 | M42: =IF(N41>0.00001,Q42-R42,0)*-1 -> #DIV/0! | N42: =MAX(N41-O42,0) -> #DIV/0! | O42: =$N$16/$N$5 -> #DIV/0! | P42: =N41*$N$4/12 -> #DIV/0! | Q42: =P42+O42 -> #DIV/0! | R42: =IF('prijem -inna mena'!$I$90=TRUE,IF($C$11>0,0.00025*N41,0),IF('prijem -inna mena'!$I$91=TRUE,IF('prijem -inna mena'!$F$91>0,0.00025*N41*-1,0),0)) -> 0
A43: 27 | B43: =IF(C42>0.00001,F43-G43,0) -> #NUM! | C43: =MAX(C42-D43,0) -> #NUM! | D43: =(F43-E43)*-1 -> #NUM! | E43: =IPMT($C$4/12,1,$C$5,C42) -> #NUM! | F43: =PMT($C$4/12,$C$5,$C$3) -> #NUM! | G43: =IF('prijem -inna mena'!$I$90=TRUE,IF($C$11>0,0.00025*C42,0),IF('prijem -inna mena'!$I$91=TRUE,IF('prijem -inna mena'!$F$91>0,0.00025*C42,0),0)) -> 0 | L43: 27 | M43: =IF(N42>0.00001,Q43-R43,0)*-1 -> #DIV/0! | N43: =MAX(N42-O43,0) -> #DIV/0! | O43: =$N$16/$N$5 -> #DIV/0! | P43: =N42*$N$4/12 -> #DIV/0! | Q43: =P43+O43 -> #DIV/0! | R43: =IF('prijem -inna mena'!$I$90=TRUE,IF($C$11>0,0.00025*N42,0),IF('prijem -inna mena'!$I$91=TRUE,IF('prijem -inna mena'!$F$91>0,0.00025*N42*-1,0),0)) -> 0
A44: 28 | B44: =IF(C43>0.00001,F44-G44,0) -> #NUM! | C44: =MAX(C43-D44,0) -> #NUM! | D44: =(F44-E44)*-1 -> #NUM! | E44: =IPMT($C$4/12,1,$C$5,C43) -> #NUM! | F44: =PMT($C$4/12,$C$5,$C$3) -> #NUM! | G44: =IF('prijem -inna mena'!$I$90=TRUE,IF($C$11>0,0.00025*C43,0),IF('prijem -inna mena'!$I$91=TRUE,IF('prijem -inna mena'!$F$91>0,0.00025*C43,0),0)) -> 0 | L44: 28 | M44: =IF(N43>0.00001,Q44-R44,0)*-1 -> #DIV/0! | N44: =MAX(N43-O44,0) -> #DIV/0! | O44: =$N$16/$N$5 -> #DIV/0! | P44: =N43*$N$4/12 -> #DIV/0! | Q44: =P44+O44 -> #DIV/0! | R44: =IF('prijem -inna mena'!$I$90=TRUE,IF($C$11>0,0.00025*N43,0),IF('prijem -inna mena'!$I$91=TRUE,IF('prijem -inna mena'!$F$91>0,0.00025*N43*-1,0),0)) -> 0
A45: 29 | B45: =IF(C44>0.00001,F45-G45,0) -> #NUM! | C45: =MAX(C44-D45,0) -> #NUM! | D45: =(F45-E45)*-1 -> #NUM! | E45: =IPMT($C$4/12,1,$C$5,C44) -> #NUM! | F45: =PMT($C$4/12,$C$5,$C$3) -> #NUM! | G45: =IF('prijem -inna mena'!$I$90=TRUE,IF($C$11>0,0.00025*C44,0),IF('prijem -inna mena'!$I$91=TRUE,IF('prijem -inna mena'!$F$91>0,0.00025*C44,0),0)) -> 0 | L45: 29 | M45: =IF(N44>0.00001,Q45-R45,0)*-1 -> #DIV/0! | N45: =MAX(N44-O45,0) -> #DIV/0! | O45: =$N$16/$N$5 -> #DIV/0! | P45: =N44*$N$4/12 -> #DIV/0! | Q45: =P45+O45 -> #DIV/0! | R45: =IF('prijem -inna mena'!$I$90=TRUE,IF($C$11>0,0.00025*N44,0),IF('prijem -inna mena'!$I$91=TRUE,IF('prijem -inna mena'!$F$91>0,0.00025*N44*-1,0),0)) -> 0
A46: 30 | B46: =IF(C45>0.00001,F46-G46,0) -> #NUM! | C46: =MAX(C45-D46,0) -> #NUM! | D46: =(F46-E46)*-1 -> #NUM! | E46: =IPMT($C$4/12,1,$C$5,C45) -> #NUM! | F46: =PMT($C$4/12,$C$5,$C$3) -> #NUM! | G46: =IF('prijem -inna mena'!$I$90=TRUE,IF($C$11>0,0.00025*C45,0),IF('prijem -inna mena'!$I$91=TRUE,IF('prijem -inna mena'!$F$91>0,0.00025*C45,0),0)) -> 0 | L46: 30 | M46: =IF(N45>0.00001,Q46-R46,0)*-1 -> #DIV/0! | N46: =MAX(N45-O46,0) -> #DIV/0! | O46: =$N$16/$N$5 -> #DIV/0! | P46: =N45*$N$4/12 -> #DIV/0! | Q46: =P46+O46 -> #DIV/0! | R46: =IF('prijem -inna mena'!$I$90=TRUE,IF($C$11>0,0.00025*N45,0),IF('prijem -inna mena'!$I$91=TRUE,IF('prijem -inna mena'!$F$91>0,0.00025*N45*-1,0),0)) -> 0
A47: 31 | B47: =IF(C46>0.00001,F47-G47,0) -> #NUM! | C47: =MAX(C46-D47,0) -> #NUM! | D47: =(F47-E47)*-1 -> #NUM! | E47: =IPMT($C$4/12,1,$C$5,C46) -> #NUM! | F47: =PMT($C$4/12,$C$5,$C$3) -> #NUM! | G47: =IF('prijem -inna mena'!$I$90=TRUE,IF($C$11>0,0.00025*C46,0),IF('prijem -inna mena'!$I$91=TRUE,IF('prijem -inna mena'!$F$91>0,0.00025*C46,0),0)) -> 0 | L47: 31 | M47: =IF(N46>0.00001,Q47-R47,0)*-1 -> #DIV/0! | N47: =MAX(N46-O47,0) -> #DIV/0! | O47: =$N$16/$N$5 -> #DIV/0! | P47: =N46*$N$4/12 -> #DIV/0! | Q47: =P47+O47 -> #DIV/0! | R47: =IF('prijem -inna mena'!$I$90=TRUE,IF($C$11>0,0.00025*N46,0),IF('prijem -inna mena'!$I$91=TRUE,IF('prijem -inna mena'!$F$91>0,0.00025*N46*-1,0),0)) -> 0
A48: 32 | B48: =IF(C47>0.00001,F48-G48,0) -> #NUM! | C48: =MAX(C47-D48,0) -> #NUM! | D48: =(F48-E48)*-1 -> #NUM! | E48: =IPMT($C$4/12,1,$C$5,C47) -> #NUM! | F48: =PMT($C$4/12,$C$5,$C$3) -> #NUM! | G48: =IF('prijem -inna mena'!$I$90=TRUE,IF($C$11>0,0.00025*C47,0),IF('prijem -inna mena'!$I$91=TRUE,IF('prijem -inna mena'!$F$91>0,0.00025*C47,0),0)) -> 0 | L48: 32 | M48: =IF(N47>0.00001,Q48-R48,0)*-1 -> #DIV/0! | N48: =MAX(N47-O48,0) -> #DIV/0! | O48: =$N$16/$N$5 -> #DIV/0! | P48: =N47*$N$4/12 -> #DIV/0! | Q48: =P48+O48 -> #DIV/0! | R48: =IF('prijem -inna mena'!$I$90=TRUE,IF($C$11>0,0.00025*N47,0),IF('prijem -inna mena'!$I$91=TRUE,IF('prijem -inna mena'!$F$91>0,0.00025*N47*-1,0),0)) -> 0
A49: 33 | B49: =IF(C48>0.00001,F49-G49,0) -> #NUM! | C49: =MAX(C48-D49,0) -> #NUM! | D49: =(F49-E49)*-1 -> #NUM! | E49: =IPMT($C$4/12,1,$C$5,C48) -> #NUM! | F49: =PMT($C$4/12,$C$5,$C$3) -> #NUM! | G49: =IF('prijem -inna mena'!$I$90=TRUE,IF($C$11>0,0.00025*C48,0),IF('prijem -inna mena'!$I$91=TRUE,IF('prijem -inna mena'!$F$91>0,0.00025*C48,0),0)) -> 0 | L49: 33 | M49: =IF(N48>0.00001,Q49-R49,0)*-1 -> #DIV/0! | N49: =MAX(N48-O49,0) -> #DIV/0! | O49: =$N$16/$N$5 -> #DIV/0! | P49: =N48*$N$4/12 -> #DIV/0! | Q49: =P49+O49 -> #DIV/0! | R49: =IF('prijem -inna mena'!$I$90=TRUE,IF($C$11>0,0.00025*N48,0),IF('prijem -inna mena'!$I$91=TRUE,IF('prijem -inna mena'!$F$91>0,0.00025*N48*-1,0),0)) -> 0
A50: 34 | B50: =IF(C49>0.00001,F50-G50,0) -> #NUM! | C50: =MAX(C49-D50,0) -> #NUM! | D50: =(F50-E50)*-1 -> #NUM! | E50: =IPMT($C$4/12,1,$C$5,C49) -> #NUM! | F50: =PMT($C$4/12,$C$5,$C$3) -> #NUM! | G50: =IF('prijem -inna mena'!$I$90=TRUE,IF($C$11>0,0.00025*C49,0),IF('prijem -inna mena'!$I$91=TRUE,IF('prijem -inna mena'!$F$91>0,0.00025*C49,0),0)) -> 0 | L50: 34 | M50: =IF(N49>0.00001,Q50-R50,0)*-1 -> #DIV/0! | N50: =MAX(N49-O50,0) -> #DIV/0! | O50: =$N$16/$N$5 -> #DIV/0! | P50: =N49*$N$4/12 -> #DIV/0! | Q50: =P50+O50 -> #DIV/0! | R50: =IF('prijem -inna mena'!$I$90=TRUE,IF($C$11>0,0.00025*N49,0),IF('prijem -inna mena'!$I$91=TRUE,IF('prijem -inna mena'!$F$91>0,0.00025*N49*-1,0),0)) -> 0
A51: 35 | B51: =IF(C50>0.00001,F51-G51,0) -> #NUM! | C51: =MAX(C50-D51,0) -> #NUM! | D51: =(F51-E51)*-1 -> #NUM! | E51: =IPMT($C$4/12,1,$C$5,C50) -> #NUM! | F51: =PMT($C$4/12,$C$5,$C$3) -> #NUM! | G51: =IF('prijem -inna mena'!$I$90=TRUE,IF($C$11>0,0.00025*C50,0),IF('prijem -inna mena'!$I$91=TRUE,IF('prijem -inna mena'!$F$91>0,0.00025*C50,0),0)) -> 0 | L51: 35 | M51: =IF(N50>0.00001,Q51-R51,0)*-1 -> #DIV/0! | N51: =MAX(N50-O51,0) -> #DIV/0! | O51: =$N$16/$N$5 -> #DIV/0! | P51: =N50*$N$4/12 -> #DIV/0! | Q51: =P51+O51 -> #DIV/0! | R51: =IF('prijem -inna mena'!$I$90=TRUE,IF($C$11>0,0.00025*N50,0),IF('prijem -inna mena'!$I$91=TRUE,IF('prijem -inna mena'!$F$91>0,0.00025*N50*-1,0),0)) -> 0
A52: 36 | B52: =IF(C51>0.00001,F52-G52,0) -> #NUM! | C52: =MAX(C51-D52,0) -> #NUM! | D52: =(F52-E52)*-1 -> #NUM! | E52: =IPMT($C$4/12,1,$C$5,C51) -> #NUM! | F52: =PMT($C$4/12,$C$5,$C$3) -> #NUM! | G52: =IF('prijem -inna mena'!$I$90=TRUE,IF($C$11>0,0.00025*C51,0),IF('prijem -inna mena'!$I$91=TRUE,IF('prijem -inna mena'!$F$91>0,0.00025*C51,0),0)) -> 0 | L52: 36 | M52: =IF(N51>0.00001,Q52-R52,0)*-1 -> #DIV/0! | N52: =MAX(N51-O52,0) -> #DIV/0! | O52: =$N$16/$N$5 -> #DIV/0! | P52: =N51*$N$4/12 -> #DIV/0! | Q52: =P52+O52 -> #DIV/0! | R52: =IF('prijem -inna mena'!$I$90=TRUE,IF($C$11>0,0.00025*N51,0),IF('prijem -inna mena'!$I$91=TRUE,IF('prijem -inna mena'!$F$91>0,0.00025*N51*-1,0),0)) -> 0
...

Sheet prijem - EUR-viac-domacnosti
C1: Kalkulačka mHypotéka
D3: Dátum zadania do systému
F4: =IF(ISBLANK(F3),"DÁTUM PODANIA!","OK") -> DÁTUM PODANIA!
D5: Číslo žiadosti
D6: Domácnosť č. 1
D8: Mesačný čistý príjem domácnosti v EUR No.1 | F8: =MAX(F9+F12+F15-F10-F13-F16,0) -> 0 | I8: MIN_VĚK_1
D9: Čistý príjem žiadateľa č.1 | F9: 0 | I9: =IF(F18=3,MIN(F20,F22,F24),IF(F18=2,MIN(F20,F22),F20)) -> 0
D10: z toho príjem z výživného a sirotského dôchodku | F10: 0
D11: Náklady bývania žiadateľa č. 1 | F11: 0
D12: Čistý príjem žiadateľa č.2 | F12: 0
D13: z toho príjem z výživného a sirotského dôchodku | F13: 0
D14: Náklady bývania žiadateľa č. 2 | F14: 0
D15: Čistý príjem žiadateľa č.3 | F15: 0
D16: z toho príjem z výživného a sirotského dôchodku | F16: 0
D17: Náklady bývania žiadateľa č. 3 | F17: 0
D18: Počet žiadatelov
D19: Dátum narodenia žiadateľa č. 1 | I19: =IF(F20<41,8,IF(F20+F84/12<65,8,MAX(8-0.25*(F20-40),3))) -> 8
D20: Vek žiadateľa č. 1 na limity | F20: =IF(F19="",0,IF(AND(DAY(F3)=DAY(F19),MONTH(F3)=MONTH(F19)),YEAR(F3)-YEAR(F19),FLOOR(YEARFRAC(F19,F3,1),1))) -> 0
D21: Dátum narodenia žiadateľa č. 2 | I21: =IF(F22<41,8,IF(F22+F84/12<65,8,MAX(8-0.25*(F22-40),3))) -> 8
D22: Vek žiadateľa č.2 na limity | F22: =IF(F21="",0,IF(AND(DAY(F3)=DAY(F21),MONTH(F3)=MONTH(F21)),YEAR(F3)-YEAR(F21),FLOOR(YEARFRAC(F21,F3,1),1))) -> 0
D23: Dátum narodenia žiadateľa č. 3 | I23: =IF(F24<41,8,IF(F24+F84/12<65,8,MAX(8-0.25*(F24-40),3))) -> 8
D24: Vek žiadateľa č.3 na limity | F24: =IF(F23="",0,IF(AND(DAY(F3)=DAY(F23),MONTH(F3)=MONTH(F23)),YEAR(F3)-YEAR(F23),FLOOR(YEARFRAC(F23,F3,1),1))) -> 0
D25: Počet žiadatelmi vyživovaných osôb
D26: Number of dependants with applicants | F26: =F18+F25 -> 0
D27: v tom detí
D28: KUGD_GOSP_1 | F28: =IF($F$26=0,0,MAX($F$26*((185*($F$26^(-0.4)))^(1-0.4))*((((F9+F12+F15)*F66/(F9+F12+F15+F38+F41+F44))/$F$26)^(0.4)),0)) -> 0
D30: Výška mesačných splátok splátkových úverov
D31: Limity kontokorentných úverov
D32: Limity kreditných kariet
D33: Výška mesačných splátok alimentov, exekúcií a iných záväzkov
D35: Domácnosť č. 2
D37: Mesačný čistý príjem domácnosti v EUR No.2 | F37: =MAX(F38+F41+F44-F39-F42-F45,0) -> 0 | I37: MIN_VĚK_2
D38: Čistý príjem žiadateľa č.1 | F38: 0 | I38: =IF(F47=3,MIN(F49,F51,F53),IF(F47=2,MIN(F49,F51),F49)) -> 0
D39: z toho príjem z výživného a sirotského dôchodku | F39: 0
D40: Náklady bývania žiadateľa č. 1 | F40: 0
D41: Čistý príjem žiadateľa č.2 | F41: 0
D42: z toho príjem z výživného a sirotského dôchodku | F42: 0
D43: Náklady bývania žiadateľa č. 2
D44: Čistý príjem žiadateľa č.3 | F44: 0
D45: z toho príjem z výživného a sirotského dôchodku | F45: 0
...

Sheet RPMN - prijem - EUR-vice-domac
A2: anuita | L2: klesajuce
B3: vyska uveru | C3: ='prijem - EUR-viac-domacnosti'!F83 -> 0 | M3: vyska uveru | N3: ='prijem - EUR-viac-domacnosti'!F83 -> 0
B4: sadzba | C4: ='prijem - EUR-viac-domacnosti'!F107 -> 0 | M4: sadzba | N4: ='prijem - EUR-viac-domacnosti'!F107 -> 0
B5: splatnost | C5: ='prijem - EUR-viac-domacnosti'!F84 -> 0 | M5: splatnost | N5: ='prijem - EUR-viac-domacnosti'!F84 -> 0
B6: cena ZP | C6: ='prijem - EUR-viac-domacnosti'!F87+'prijem - EUR-viac-domacnosti'!F94+'prijem - EUR-viac-domacnosti'!F101 -> 0 | M6: cena ZP | N6: ='prijem - EUR-viac-domacnosti'!F87+'prijem - EUR-viac-domacnosti'!F94+'prijem - EUR-viac-domacnosti'!F101 -> 0
B7: poistné za rok | C7: ='prijem - EUR-viac-domacnosti'!F88+'prijem - EUR-viac-domacnosti'!F95+'prijem - EUR-viac-domacnosti'!F102 -> 0 | M7: poistné za rok | N7: ='prijem - EUR-viac-domacnosti'!F88+'prijem - EUR-viac-domacnosti'!F95+'prijem - EUR-viac-domacnosti'!F102 -> 0
B8: poistné za celú dobu | C8: ='prijem - EUR-viac-domacnosti'!F89+'prijem - EUR-viac-domacnosti'!F96+'prijem - EUR-viac-domacnosti'!F103 -> 0 | M8: poistné za celú dobu | N8: ='prijem - EUR-viac-domacnosti'!F89+'prijem - EUR-viac-domacnosti'!F96+'prijem - EUR-viac-domacnosti'!F103 -> 0
B9: vklad do katastru | C9: ='prijem - EUR-viac-domacnosti'!E138+'prijem - EUR-viac-domacnosti'!E139+'prijem - EUR-viac-domacnosti'!E140 -> 0 | M9: vklad do katastru | N9: ='prijem - EUR-viac-domacnosti'!E138+'prijem - EUR-viac-domacnosti'!E139+'prijem - EUR-viac-domacnosti'!E140 -> 0
B10: LCI | C10: #REF! | M10: LCI | N10: #REF!
B11: Life | C11: ='prijem - EUR-viac-domacnosti'!F120 -> 0 | M11: Life | N11: ='prijem - EUR-viac-domacnosti'!F120 -> 0
B12: RPMN | C12: =(1+IRR(B16:B496,1%))^12-1 -> #VALUE! | M12: RPMN | N12: =(1+IRR(M16:M496,1%))^12-1 -> #VALUE!
B13: celkova zaplatena | C13: =(SUM(B17:B496)*-1)+C6+C8+C9+H17 -> #NUM! | M13: celkova zaplatena | N13: =(SUM(M17:M496)*-1)+N6+N8+N9+S17 -> #DIV/0!
B15: CF | C15: zostatok | M15: CF | N15: zostatok
A16: mesiac | B16: =C3-C6-C7-C9-C11-H17 -> 0 | C16: =C3 -> 0 | D16: istina | E16: urok | F16: splatka | G16: splatka LI | H16: LI nezapoč | L16: mesiac | M16: =N3-N6-N7-N9-S17 -> 0 | N16: =N3 -> 0 | O16: istina | P16: urok | Q16: splatka | R16: splatka LI | S16: LI nezapoč
A17: 1 | B17: =IF(C16>0.00001,F17-G17,0) -> 0 | C17: =MAX(C16-D17,0) -> #NUM! | D17: =(F17-E17)*-1 -> #NUM! | E17: =IPMT($C$4/12,1,$C$5,C16) -> #NUM! | F17: =PMT($C$4/12,$C$5,$C$3) -> #NUM! | H17: ='prijem - EUR-viac-domacnosti'!F121 -> 0 | L17: 1 | M17: =IF(N16>0.00001,Q17-R17,0)*-1 -> 0 | N17: =MAX(N16-O17,0) -> #DIV/0! | O17: =$N$16/$N$5 -> #DIV/0! | P17: =N16*$N$4/12 -> 0 | Q17: =P17+O17 -> #DIV/0! | S17: ='prijem - EUR-viac-domacnosti'!F121 -> 0
A18: 2 | B18: =IF(C17>0.00001,F18-G18,0) -> #NUM! | C18: =MAX(C17-D18,0) -> #NUM! | D18: =(F18-E18)*-1 -> #NUM! | E18: =IPMT($C$4/12,1,$C$5,C17) -> #NUM! | F18: =PMT($C$4/12,$C$5,$C$3) -> #NUM! | L18: 2 | M18: =IF(N17>0.00001,Q18-R18,0)*-1 -> #DIV/0! | N18: =MAX(N17-O18,0) -> #DIV/0! | O18: =$N$16/$N$5 -> #DIV/0! | P18: =N17*$N$4/12 -> #DIV/0! | Q18: =P18+O18 -> #DIV/0!
A19: 3 | B19: =IF(C18>0.00001,F19-G19,0) -> #NUM! | C19: =MAX(C18-D19,0) -> #NUM! | D19: =(F19-E19)*-1 -> #NUM! | E19: =IPMT($C$4/12,1,$C$5,C18) -> #NUM! | F19: =PMT($C$4/12,$C$5,$C$3) -> #NUM! | L19: 3 | M19: =IF(N18>0.00001,Q19-R19,0)*-1 -> #DIV/0! | N19: =MAX(N18-O19,0) -> #DIV/0! | O19: =$N$16/$N$5 -> #DIV/0! | P19: =N18*$N$4/12 -> #DIV/0! | Q19: =P19+O19 -> #DIV/0!
A20: 4 | B20: =IF(C19>0.00001,F20-G20,0) -> #NUM! | C20: =MAX(C19-D20,0) -> #NUM! | D20: =(F20-E20)*-1 -> #NUM! | E20: =IPMT($C$4/12,1,$C$5,C19) -> #NUM! | F20: =PMT($C$4/12,$C$5,$C$3) -> #NUM! | L20: 4 | M20: =IF(N19>0.00001,Q20-R20,0)*-1 -> #DIV/0! | N20: =MAX(N19-O20,0) -> #DIV/0! | O20: =$N$16/$N$5 -> #DIV/0! | P20: =N19*$N$4/12 -> #DIV/0! | Q20: =P20+O20 -> #DIV/0!
A21: 5 | B21: =IF(C20>0.00001,F21-G21,0) -> #NUM! | C21: =MAX(C20-D21,0) -> #NUM! | D21: =(F21-E21)*-1 -> #NUM! | E21: =IPMT($C$4/12,1,$C$5,C20) -> #NUM! | F21: =PMT($C$4/12,$C$5,$C$3) -> #NUM! | L21: 5 | M21: =IF(N20>0.00001,Q21-R21,0)*-1 -> #DIV/0! | N21: =MAX(N20-O21,0) -> #DIV/0! | O21: =$N$16/$N$5 -> #DIV/0! | P21: =N20*$N$4/12 -> #DIV/0! | Q21: =P21+O21 -> #DIV/0!
A22: 6 | B22: =IF(C21>0.00001,F22-G22,0) -> #NUM! | C22: =MAX(C21-D22,0) -> #NUM! | D22: =(F22-E22)*-1 -> #NUM! | E22: =IPMT($C$4/12,1,$C$5,C21) -> #NUM! | F22: =PMT($C$4/12,$C$5,$C$3) -> #NUM! | L22: 6 | M22: =IF(N21>0.00001,Q22-R22,0)*-1 -> #DIV/0! | N22: =MAX(N21-O22,0) -> #DIV/0! | O22: =$N$16/$N$5 -> #DIV/0! | P22: =N21*$N$4/12 -> #DIV/0! | Q22: =P22+O22 -> #DIV/0!
A23: 7 | B23: =IF(C22>0.00001,F23-G23,0) -> #NUM! | C23: =MAX(C22-D23,0) -> #NUM! | D23: =(F23-E23)*-1 -> #NUM! | E23: =IPMT($C$4/12,1,$C$5,C22) -> #NUM! | F23: =PMT($C$4/12,$C$5,$C$3) -> #NUM! | L23: 7 | M23: =IF(N22>0.00001,Q23-R23,0)*-1 -> #DIV/0! | N23: =MAX(N22-O23,0) -> #DIV/0! | O23: =$N$16/$N$5 -> #DIV/0! | P23: =N22*$N$4/12 -> #DIV/0! | Q23: =P23+O23 -> #DIV/0!
A24: 8 | B24: =IF(C23>0.00001,F24-G24,0) -> #NUM! | C24: =MAX(C23-D24,0) -> #NUM! | D24: =(F24-E24)*-1 -> #NUM! | E24: =IPMT($C$4/12,1,$C$5,C23) -> #NUM! | F24: =PMT($C$4/12,$C$5,$C$3) -> #NUM! | L24: 8 | M24: =IF(N23>0.00001,Q24-R24,0)*-1 -> #DIV/0! | N24: =MAX(N23-O24,0) -> #DIV/0! | O24: =$N$16/$N$5 -> #DIV/0! | P24: =N23*$N$4/12 -> #DIV/0! | Q24: =P24+O24 -> #DIV/0!
A25: 9 | B25: =IF(C24>0.00001,F25-G25,0) -> #NUM! | C25: =MAX(C24-D25,0) -> #NUM! | D25: =(F25-E25)*-1 -> #NUM! | E25: =IPMT($C$4/12,1,$C$5,C24) -> #NUM! | F25: =PMT($C$4/12,$C$5,$C$3) -> #NUM! | L25: 9 | M25: =IF(N24>0.00001,Q25-R25,0)*-1 -> #DIV/0! | N25: =MAX(N24-O25,0) -> #DIV/0! | O25: =$N$16/$N$5 -> #DIV/0! | P25: =N24*$N$4/12 -> #DIV/0! | Q25: =P25+O25 -> #DIV/0!
A26: 10 | B26: =IF(C25>0.00001,F26-G26,0) -> #NUM! | C26: =MAX(C25-D26,0) -> #NUM! | D26: =(F26-E26)*-1 -> #NUM! | E26: =IPMT($C$4/12,1,$C$5,C25) -> #NUM! | F26: =PMT($C$4/12,$C$5,$C$3) -> #NUM! | L26: 10 | M26: =IF(N25>0.00001,Q26-R26,0)*-1 -> #DIV/0! | N26: =MAX(N25-O26,0) -> #DIV/0! | O26: =$N$16/$N$5 -> #DIV/0! | P26: =N25*$N$4/12 -> #DIV/0! | Q26: =P26+O26 -> #DIV/0!
A27: 11 | B27: =IF(C26>0.00001,F27-G27,0) -> #NUM! | C27: =MAX(C26-D27,0) -> #NUM! | D27: =(F27-E27)*-1 -> #NUM! | E27: =IPMT($C$4/12,1,$C$5,C26) -> #NUM! | F27: =PMT($C$4/12,$C$5,$C$3) -> #NUM! | L27: 11 | M27: =IF(N26>0.00001,Q27-R27,0)*-1 -> #DIV/0! | N27: =MAX(N26-O27,0) -> #DIV/0! | O27: =$N$16/$N$5 -> #DIV/0! | P27: =N26*$N$4/12 -> #DIV/0! | Q27: =P27+O27 -> #DIV/0!
A28: 12 | B28: =IF(C27>0.00001,F28-G28,0) -> #NUM! | C28: =MAX(C27-D28,0) -> #NUM! | D28: =(F28-E28)*-1 -> #NUM! | E28: =IPMT($C$4/12,1,$C$5,C27) -> #NUM! | F28: =PMT($C$4/12,$C$5,$C$3) -> #NUM! | L28: 12 | M28: =IF(N27>0.00001,Q28-R28,0)*-1 -> #DIV/0! | N28: =MAX(N27-O28,0) -> #DIV/0! | O28: =$N$16/$N$5 -> #DIV/0! | P28: =N27*$N$4/12 -> #DIV/0! | Q28: =P28+O28 -> #DIV/0!
A29: 13 | B29: =IF(C28>0.00001,F29-G29,0) -> #NUM! | C29: =MAX(C28-D29,0) -> #NUM! | D29: =(F29-E29)*-1 -> #NUM! | E29: =IPMT($C$4/12,1,$C$5,C28) -> #NUM! | F29: =PMT($C$4/12,$C$5,$C$3) -> #NUM! | L29: 13 | M29: =IF(N28>0.00001,Q29-R29,0)*-1 -> #DIV/0! | N29: =MAX(N28-O29,0) -> #DIV/0! | O29: =$N$16/$N$5 -> #DIV/0! | P29: =N28*$N$4/12 -> #DIV/0! | Q29: =P29+O29 -> #DIV/0!
... A40: 24 | B40: =IF(C39>0.00001,F40-G40,0) -> #NUM! | C40: =MAX(C39-D40,0) -> #NUM! | D40: =(F40-E40)*-1 -> #NUM! | E40: =IPMT($C$4/12,1,$C$5,C39) -> #NUM! | F40: =PMT($C$4/12,$C$5,$C$3) -> #NUM! | L40: 24 | M40: =IF(N39>0.00001,Q40-R40,0)*-1 -> #DIV/0! | N40: =MAX(N39-O40,0) -> #DIV/0! | O40: =$N$16/$N$5 -> #DIV/0! | P40: =N39*$N$4/12 -> #DIV/0! | Q40: =P40+O40 -> #DIV/0!
A41: 25 | B41: =IF(C40>0.00001,F41-G41,0) -> #NUM! | C41: =MAX(C40-D41,0) -> #NUM! | D41: =(F41-E41)*-1 -> #NUM! | E41: =IPMT($C$4/12,1,$C$5,C40) -> #NUM! | F41: =PMT($C$4/12,$C$5,$C$3) -> #NUM! | G41: =IF('prijem - EUR-viac-domacnosti'!$I$120=TRUE,IF($C$11>0,0.00025*C40,0),IF('prijem - EUR-viac-domacnosti'!$I$121=TRUE,IF('prijem - EUR-viac-domacnosti'!$F$121>0,0.00025*C40,0),0)) -> 0 | L41: 25 | M41: =IF(N40>0.00001,Q41-R41,0)*-1 -> #DIV/0! | N41: =MAX(N40-O41,0) -> #DIV/0! | O41: =$N$16/$N$5 -> #DIV/0! | P41: =N40*$N$4/12 -> #DIV/0! | Q41: =P41+O41 -> #DIV/0! | R41: =IF('prijem - EUR-viac-domacnosti'!$I$120=TRUE,IF($C$11>0,0.00025*N40,0),IF('prijem - EUR-viac-domacnosti'!$I$121=TRUE,IF('prijem - EUR-viac-domacnosti'!$F$121>0,0.00025*N40*-1,0),0)) -> 0
A42: 26 | B42: =IF(C41>0.00001,F42-G42,0) -> #NUM! | C42: =MAX(C41-D42,0) -> #NUM! | D42: =(F42-E42)*-1 -> #NUM! | E42: =IPMT($C$4/12,1,$C$5,C41) -> #NUM! | F42: =PMT($C$4/12,$C$5,$C$3) -> #NUM! | G42: =IF('prijem - EUR-viac-domacnosti'!$I$120=TRUE,IF($C$11>0,0.00025*C41,0),IF('prijem - EUR-viac-domacnosti'!$I$121=TRUE,IF('prijem - EUR-viac-domacnosti'!$F$121>0,0.00025*C41,0),0)) -> 0 | L42: 26 | M42: =IF(N41>0.00001,Q42-R42,0)*-1 -> #DIV/0! | N42: =MAX(N41-O42,0) -> #DIV/0! | O42: =$N$16/$N$5 -> #DIV/0! | P42: =N41*$N$4/12 -> #DIV/0! | Q42: =P42+O42 -> #DIV/0! | R42: =IF('prijem - EUR-viac-domacnosti'!$I$120=TRUE,IF($C$11>0,0.00025*N41,0),IF('prijem - EUR-viac-domacnosti'!$I$121=TRUE,IF('prijem - EUR-viac-domacnosti'!$F$121>0,0.00025*N41*-1,0),0)) -> 0
A43: 27 | B43: =IF(C42>0.00001,F43-G43,0) -> #NUM! | C43: =MAX(C42-D43,0) -> #NUM! | D43: =(F43-E43)*-1 -> #NUM! | E43: =IPMT($C$4/12,1,$C$5,C42) -> #NUM! | F43: =PMT($C$4/12,$C$5,$C$3) -> #NUM! | G43: =IF('prijem - EUR-viac-domacnosti'!$I$120=TRUE,IF($C$11>0,0.00025*C42,0),IF('prijem - EUR-viac-domacnosti'!$I$121=TRUE,IF('prijem - EUR-viac-domacnosti'!$F$121>0,0.00025*C42,0),0)) -> 0 | L43: 27 | M43: =IF(N42>0.00001,Q43-R43,0)*-1 -> #DIV/0! | N43: =MAX(N42-O43,0) -> #DIV/0! | O43: =$N$16/$N$5 -> #DIV/0! | P43: =N42*$N$4/12 -> #DIV/0! | Q43: =P43+O43 -> #DIV/0! | R43: =IF('prijem - EUR-viac-domacnosti'!$I$120=TRUE,IF($C$11>0,0.00025*N42,0),IF('prijem - EUR-viac-domacnosti'!$I$121=TRUE,IF('prijem - EUR-viac-domacnosti'!$F$121>0,0.00025*N42*-1,0),0)) -> 0
A44: 28 | B44: =IF(C43>0.00001,F44-G44,0) -> #NUM! | C44: =MAX(C43-D44,0) -> #NUM! | D44: =(F44-E44)*-1 -> #NUM! | E44: =IPMT($C$4/12,1,$C$5,C43) -> #NUM! | F44: =PMT($C$4/12,$C$5,$C$3) -> #NUM! | G44: =IF('prijem - EUR-viac-domacnosti'!$I$120=TRUE,IF($C$11>0,0.00025*C43,0),IF('prijem - EUR-viac-domacnosti'!$I$121=TRUE,IF('prijem - EUR-viac-domacnosti'!$F$121>0,0.00025*C43,0),0)) -> 0 | L44: 28 | M44: =IF(N43>0.00001,Q44-R44,0)*-1 -> #DIV/0! | N44: =MAX(N43-O44,0) -> #DIV/0! | O44: =$N$16/$N$5 -> #DIV/0! | P44: =N43*$N$4/12 -> #DIV/0! | Q44: =P44+O44 -> #DIV/0! | R44: =IF('prijem - EUR-viac-domacnosti'!$I$120=TRUE,IF($C$11>0,0.00025*N43,0),IF('prijem - EUR-viac-domacnosti'!$I$121=TRUE,IF('prijem - EUR-viac-domacnosti'!$F$121>0,0.00025*N43*-1,0),0)) -> 0
A45: 29 | B45: =IF(C44>0.00001,F45-G45,0) -> #NUM! | C45: =MAX(C44-D45,0) -> #NUM! | D45: =(F45-E45)*-1 -> #NUM! | E45: =IPMT($C$4/12,1,$C$5,C44) -> #NUM! | F45: =PMT($C$4/12,$C$5,$C$3) -> #NUM! | G45: =IF('prijem - EUR-viac-domacnosti'!$I$120=TRUE,IF($C$11>0,0.00025*C44,0),IF('prijem - EUR-viac-domacnosti'!$I$121=TRUE,IF('prijem - EUR-viac-domacnosti'!$F$121>0,0.00025*C44,0),0)) -> 0 | L45: 29 | M45: =IF(N44>0.00001,Q45-R45,0)*-1 -> #DIV/0! | N45: =MAX(N44-O45,0) -> #DIV/0! | O45: =$N$16/$N$5 -> #DIV/0! | P45: =N44*$N$4/12 -> #DIV/0! | Q45: =P45+O45 -> #DIV/0! | R45: =IF('prijem - EUR-viac-domacnosti'!$I$120=TRUE,IF($C$11>0,0.00025*N44,0),IF('prijem - EUR-viac-domacnosti'!$I$121=TRUE,IF('prijem - EUR-viac-domacnosti'!$F$121>0,0.00025*N44*-1,0),0)) -> 0
A46: 30 | B46: =IF(C45>0.00001,F46-G46,0) -> #NUM! | C46: =MAX(C45-D46,0) -> #NUM! | D46: =(F46-E46)*-1 -> #NUM! | E46: =IPMT($C$4/12,1,$C$5,C45) -> #NUM! | F46: =PMT($C$4/12,$C$5,$C$3) -> #NUM! | G46: =IF('prijem - EUR-viac-domacnosti'!$I$120=TRUE,IF($C$11>0,0.00025*C45,0),IF('prijem - EUR-viac-domacnosti'!$I$121=TRUE,IF('prijem - EUR-viac-domacnosti'!$F$121>0,0.00025*C45,0),0)) -> 0 | L46: 30 | M46: =IF(N45>0.00001,Q46-R46,0)*-1 -> #DIV/0! | N46: =MAX(N45-O46,0) -> #DIV/0! | O46: =$N$16/$N$5 -> #DIV/0! | P46: =N45*$N$4/12 -> #DIV/0! | Q46: =P46+O46 -> #DIV/0! | R46: =IF('prijem - EUR-viac-domacnosti'!$I$120=TRUE,IF($C$11>0,0.00025*N45,0),IF('prijem - EUR-viac-domacnosti'!$I$121=TRUE,IF('prijem - EUR-viac-domacnosti'!$F$121>0,0.00025*N45*-1,0),0)) -> 0
A47: 31 | B47: =IF(C46>0.00001,F47-G47,0) -> #NUM! | C47: =MAX(C46-D47,0) -> #NUM! | D47: =(F47-E47)*-1 -> #NUM! | E47: =IPMT($C$4/12,1,$C$5,C46) -> #NUM! | F47: =PMT($C$4/12,$C$5,$C$3) -> #NUM! | G47: =IF('prijem - EUR-viac-domacnosti'!$I$120=TRUE,IF($C$11>0,0.00025*C46,0),IF('prijem - EUR-viac-domacnosti'!$I$121=TRUE,IF('prijem - EUR-viac-domacnosti'!$F$121>0,0.00025*C46,0),0)) -> 0 | L47: 31 | M47: =IF(N46>0.00001,Q47-R47,0)*-1 -> #DIV/0! | N47: =MAX(N46-O47,0) -> #DIV/0! | O47: =$N$16/$N$5 -> #DIV/0! | P47: =N46*$N$4/12 -> #DIV/0! | Q47: =P47+O47 -> #DIV/0! | R47: =IF('prijem - EUR-viac-domacnosti'!$I$120=TRUE,IF($C$11>0,0.00025*N46,0),IF('prijem - EUR-viac-domacnosti'!$I$121=TRUE,IF('prijem - EUR-viac-domacnosti'!$F$121>0,0.00025*N46*-1,0),0)) -> 0
A48: 32 | B48: =IF(C47>0.00001,F48-G48,0) -> #NUM! | C48: =MAX(C47-D48,0) -> #NUM! | D48: =(F48-E48)*-1 -> #NUM! | E48: =IPMT($C$4/12,1,$C$5,C47) -> #NUM! | F48: =PMT($C$4/12,$C$5,$C$3) -> #NUM! | G48: =IF('prijem - EUR-viac-domacnosti'!$I$120=TRUE,IF($C$11>0,0.00025*C47,0),IF('prijem - EUR-viac-domacnosti'!$I$121=TRUE,IF('prijem - EUR-viac-domacnosti'!$F$121>0,0.00025*C47,0),0)) -> 0 | L48: 32 | M48: =IF(N47>0.00001,Q48-R48,0)*-1 -> #DIV/0! | N48: =MAX(N47-O48,0) -> #DIV/0! | O48: =$N$16/$N$5 -> #DIV/0! | P48: =N47*$N$4/12 -> #DIV/0! | Q48: =P48+O48 -> #DIV/0! | R48: =IF('prijem - EUR-viac-domacnosti'!$I$120=TRUE,IF($C$11>0,0.00025*N47,0),IF('prijem - EUR-viac-domacnosti'!$I$121=TRUE,IF('prijem - EUR-viac-domacnosti'!$F$121>0,0.00025*N47*-1,0),0)) -> 0
A49: 33 | B49: =IF(C48>0.00001,F49-G49,0) -> #NUM! | C49: =MAX(C48-D49,0) -> #NUM! | D49: =(F49-E49)*-1 -> #NUM! | E49: =IPMT($C$4/12,1,$C$5,C48) -> #NUM! | F49: =PMT($C$4/12,$C$5,$C$3) -> #NUM! | G49: =IF('prijem - EUR-viac-domacnosti'!$I$120=TRUE,IF($C$11>0,0.00025*C48,0),IF('prijem - EUR-viac-domacnosti'!$I$121=TRUE,IF('prijem - EUR-viac-domacnosti'!$F$121>0,0.00025*C48,0),0)) -> 0 | L49: 33 | M49: =IF(N48>0.00001,Q49-R49,0)*-1 -> #DIV/0! | N49: =MAX(N48-O49,0) -> #DIV/0! | O49: =$N$16/$N$5 -> #DIV/0! | P49: =N48*$N$4/12 -> #DIV/0! | Q49: =P49+O49 -> #DIV/0! | R49: =IF('prijem - EUR-viac-domacnosti'!$I$120=TRUE,IF($C$11>0,0.00025*N48,0),IF('prijem - EUR-viac-domacnosti'!$I$121=TRUE,IF('prijem - EUR-viac-domacnosti'!$F$121>0,0.00025*N48*-1,0),0)) -> 0
A50: 34 | B50: =IF(C49>0.00001,F50-G50,0) -> #NUM! | C50: =MAX(C49-D50,0) -> #NUM! | D50: =(F50-E50)*-1 -> #NUM! | E50: =IPMT($C$4/12,1,$C$5,C49) -> #NUM! | F50: =PMT($C$4/12,$C$5,$C$3) -> #NUM! | G50: =IF('prijem - EUR-viac-domacnosti'!$I$120=TRUE,IF($C$11>0,0.00025*C49,0),IF('prijem - EUR-viac-domacnosti'!$I$121=TRUE,IF('prijem - EUR-viac-domacnosti'!$F$121>0,0.00025*C49,0),0)) -> 0 | L50: 34 | M50: =IF(N49>0.00001,Q50-R50,0)*-1 -> #DIV/0! | N50: =MAX(N49-O50,0) -> #DIV/0! | O50: =$N$16/$N$5 -> #DIV/0! | P50: =N49*$N$4/12 -> #DIV/0! | Q50: =P50+O50 -> #DIV/0! | R50: =IF('prijem - EUR-viac-domacnosti'!$I$120=TRUE,IF($C$11>0,0.00025*N49,0),IF('prijem - EUR-viac-domacnosti'!$I$121=TRUE,IF('prijem - EUR-viac-domacnosti'!$F$121>0,0.00025*N49*-1,0),0)) -> 0
A51: 35 | B51: =IF(C50>0.00001,F51-G51,0) -> #NUM! | C51: =MAX(C50-D51,0) -> #NUM! | D51: =(F51-E51)*-1 -> #NUM! | E51: =IPMT($C$4/12,1,$C$5,C50) -> #NUM! | F51: =PMT($C$4/12,$C$5,$C$3) -> #NUM! | G51: =IF('prijem - EUR-viac-domacnosti'!$I$120=TRUE,IF($C$11>0,0.00025*C50,0),IF('prijem - EUR-viac-domacnosti'!$I$121=TRUE,IF('prijem - EUR-viac-domacnosti'!$F$121>0,0.00025*C50,0),0)) -> 0 | L51: 35 | M51: =IF(N50>0.00001,Q51-R51,0)*-1 -> #DIV/0! | N51: =MAX(N50-O51,0) -> #DIV/0! | O51: =$N$16/$N$5 -> #DIV/0! | P51: =N50*$N$4/12 -> #DIV/0! | Q51: =P51+O51 -> #DIV/0! | R51: =IF('prijem - EUR-viac-domacnosti'!$I$120=TRUE,IF($C$11>0,0.00025*N50,0),IF('prijem - EUR-viac-domacnosti'!$I$121=TRUE,IF('prijem - EUR-viac-domacnosti'!$F$121>0,0.00025*N50*-1,0),0)) -> 0
A52: 36 | B52: =IF(C51>0.00001,F52-G52,0) -> #NUM! | C52: =MAX(C51-D52,0) -> #NUM! | D52: =(F52-E52)*-1 -> #NUM! | E52: =IPMT($C$4/12,1,$C$5,C51) -> #NUM! | F52: =PMT($C$4/12,$C$5,$C$3) -> #NUM! | G52: =IF('prijem - EUR-viac-domacnosti'!$I$120=TRUE,IF($C$11>0,0.00025*C51,0),IF('prijem - EUR-viac-domacnosti'!$I$121=TRUE,IF('prijem - EUR-viac-domacnosti'!$F$121>0,0.00025*C51,0),0)) -> 0 | L52: 36 | M52: =IF(N51>0.00001,Q52-R52,0)*-1 -> #DIV/0! | N52: =MAX(N51-O52,0) -> #DIV/0! | O52: =$N$16/$N$5 -> #DIV/0! | P52: =N51*$N$4/12 -> #DIV/0! | Q52: =P52+O52 -> #DIV/0! | R52: =IF('prijem - EUR-viac-domacnosti'!$I$120=TRUE,IF($C$11>0,0.00025*N51,0),IF('prijem - EUR-viac-domacnosti'!$I$121=TRUE,IF('prijem - EUR-viac-domacnosti'!$F$121>0,0.00025*N51*-1,0),0)) -> 0
...

Sheet prijem_zahranicie - viac-dom
C1: Kalkulačka mHypotéka
D3: Jméno klienta
F4: =IF(ISBLANK(F3),"DÁTUM PODANIA!","OK") -> DÁTUM PODANIA!
D5: Číslo žádosti
D7: Mesačný čistý príjem domácnosti v EUR (prepočtený dle veku) No.1 | F7: =F9+F11+F12+F14+F15+F17 -> 0
D8: Mesačný čistý príjem domácnosti v EUR (neprepočtený dle veku) No.1 | F8: =F10+F11+F13+F14+F16+F17 -> 0
D9: Čistý príjem žiadateľa č.1 zo závislej činnosti alebo živnosti | F9: =IF(F21="","0",(F10*(F86-MIN(MAX(F21+F86-744,0),F86))/F86)+(F10*0.85*MIN(MAX(F21+F86-744,0),F86)/F86)) -> 0
D10: Čistý príjem žiadateľa č.1 zo závislej činnosti alebo živnosti
D11: Čistý príjem žiadateľa č.1 z inej činnosti
D12: Čistý príjem žiadateľa č.2 zo závislej činnosti alebo živnosti | F12: =IF(F24="","0",(F13*(F86-MIN(MAX(F24+F86-744,0),F86))/F86)+(F13*0.85*MIN(MAX(F24+F86-744,0),F86)/F86)) -> 0
D13: Čistý príjem žiadateľa č.2 zo závislej činnosti alebo živnosti
D14: Čistý príjem žiadateľa č.2 z inej činnosti
D15: Čistý príjem žiadateľa č.3 zo závislej činnosti alebo živnosti | F15: =IF(F27="","0",(F16*(F86-MIN(MAX(F27+F86-744,0),F86))/F86)+(F16*0.85*MIN(MAX(F27+F86-744,0),F86)/F86)) -> 0
D16: Čistý príjem žiadateľa č.3 zo závislej činnosti alebo živnosti
D17: Čistý príjem žiadateľa č.3 z inej činnosti
D18: Počet žiadatelov
D19: Dátum narodenia žiadateľa č.1
D20: Vek žiadateľa č.1 na limity | F20: =IF(F19="","",YEAR(F3)-YEAR(F19))
D21: Vek žiadateľa č.1 v mesiacoch | F21: =IF(F19="","",(DATEDIF(F19,F3,"M"))+(IF((DAY(F19)-DAY(F3))<=0,0,1)))
D22: Dátum narodenia žiadateľa č. 2
D23: Vek žiadateľa č.2 na limity | F23: =IF(F22="","",YEAR(F3)-YEAR(F22))
D24: Vek žiadateľa č.2 v mesiacoch | F24: =IF(F22="","",(DATEDIF(F22,F3,"M"))+(IF((DAY(F22)-DAY(F3))<=0,0,1)))
D25: Dátum narodenia žiadateľa č. 3
D26: Vek žiadateľa č.3 na limity | F26: =IF(F25="","",YEAR(F3)-YEAR(F25))
D27: Vek žiadateľa č.3 v mesiacoch | F27: =IF(F25="","",(DATEDIF(F25,F3,"M"))+(IF((DAY(F25)-DAY(F3))<=0,0,1)))
D28: Počet žiadatelmi vyživovaných osôb | F28: 0
D29: Number of dependants with applicants | F29: =$F$18+$F$28 -> 0
D30: v tom detí | F30: 0
D31: Available income (including household expenses) | F31: =MAX(0.95*(F7-MAX($F$32,$F$33)),0) -> 0
